Workbook

Sheet Forms貼り付け
A1: Microsoft Forms のエクスポート（Excel）を、このシートのA3セルからそのまま貼り付けてください。
A2: 前提：質問タイトルに 'Q1'〜'Q50' が含まれていること（例：'Q1. 〜'）。自動で列を検出します。

Sheet 整形回答
A1: 整形回答（Forms貼り付けの列を自動検出してA/B/C/Dに正規化）
A2: Forms貼り付け!A3行＝ヘッダ、A4行以降＝回答の前提。ヘッダにQ1〜Q50が含まれていれば自動で列を拾います。
A3: 列検出（自動） | B3: =IFERROR(XMATCH("*名前*",Forms貼り付け!$A$3:$AZ$3,2),"") | C3: =IFERROR(XMATCH("*メール*",Forms貼り付け!$A$3:$AZ$3,2),"") | D3: =IFERROR(XMATCH("*開始*",Forms貼り付け!$A$3:$AZ$3,2),"") | E3: =IFERROR(XMATCH("*完了*",Forms貼り付け!$A$3:$AZ$3,2),"") | F3: =IFERROR(XMATCH("*Q1*",Forms貼り付け!$A$3:$AZ$3,2),"") | G3: =IFERROR(XMATCH("*Q2*",Forms貼り付け!$A$3:$AZ$3,2),"") | H3: =IFERROR(XMATCH("*Q3*",Forms貼り付け!$A$3:$AZ$3,2),"") | I3: =IFERROR(XMATCH("*Q4*",Forms貼り付け!$A$3:$AZ$3,2),"") | J3: =IFERROR(XMATCH("*Q5*",Forms貼り付け!$A$3:$AZ$3,2),"") | K3: =IFERROR(XMATCH("*Q6*",Forms貼り付け!$A$3:$AZ$3,2),"") | L3: =IFERROR(XMATCH("*Q7*",Forms貼り付け!$A$3:$AZ$3,2),"") | M3: =IFERROR(XMATCH("*Q8*",Forms貼り付け!$A$3:$AZ$3,2),"") | N3: =IFERROR(XMATCH("*Q9*",Forms貼り付け!$A$3:$AZ$3,2),"") | O3: =IFERROR(XMATCH("*Q10*",Forms貼り付け!$A$3:$AZ$3,2),"") | P3: =IFERROR(XMATCH("*Q11*",Forms貼り付け!$A$3:$AZ$3,2),"") | Q3: =IFERROR(XMATCH("*Q12*",Forms貼り付け!$A$3:$AZ$3,2),"") | R3: =IFERROR(XMATCH("*Q13*",Forms貼り付け!$A$3:$AZ$3,2),"") | S3: =IFERROR(XMATCH("*Q14*",Forms貼り付け!$A$3:$AZ$3,2),"") | T3: =IFERROR(XMATCH("*Q15*",Forms貼り付け!$A$3:$AZ$3,2),"") | U3: =IFERROR(XMATCH("*Q16*",Forms貼り付け!$A$3:$AZ$3,2),"") | V3: =IFERROR(XMATCH("*Q17*",Forms貼り付け!$A$3:$AZ$3,2),"") | W3: =IFERROR(XMATCH("*Q18*",Forms貼り付け!$A$3:$AZ$3,2),"") | X3: =IFERROR(XMATCH("*Q19*",Forms貼り付け!$A$3:$AZ$3,2),"") | Y3: =IFERROR(XMATCH("*Q20*",Forms貼り付け!$A$3:$AZ$3,2),"") | Z3: =IFERROR(XMATCH("*Q21*",Forms貼り付け!$A$3:$AZ$3,2),"") | AA3: =IFERROR(XMATCH("*Q22*",Forms貼り付け!$A$3:$AZ$3,2),"") | AB3: =IFERROR(XMATCH("*Q23*",Forms貼り付け!$A$3:$AZ$3,2),"") | AC3: =IFERROR(XMATCH("*Q24*",Forms貼り付け!$A$3:$AZ$3,2),"") | AD3: =IFERROR(XMATCH("*Q25*",Forms貼り付け!$A$3:$AZ$3,2),"") | AE3: =IFERROR(XMATCH("*Q26*",Forms貼り付け!$A$3:$AZ$3,2),"") | AF3: =IFERROR(XMATCH("*Q27*",Forms貼り付け!$A$3:$AZ$3,2),"") | AG3: =IFERROR(XMATCH("*Q28*",Forms貼り付け!$A$3:$AZ$3,2),"") | AH3: =IFERROR(XMATCH("*Q29*",Forms貼り付け!$A$3:$AZ$3,2),"") | AI3: =IFERROR(XMATCH("*Q30*",Forms貼り付け!$A$3:$AZ$3,2),"") | AJ3: =IFERROR(XMATCH("*Q31*",Forms貼り付け!$A$3:$AZ$3,2),"") | AK3: =IFERROR(XMATCH("*Q32*",Forms貼り付け!$A$3:$AZ$3,2),"") | AL3: =IFERROR(XMATCH("*Q33*",Forms貼り付け!$A$3:$AZ$3,2),"") | AM3: =IFERROR(XMATCH("*Q34*",Forms貼り付け!$A$3:$AZ$3,2),"") | AN3: =IFERROR(XMATCH("*Q35*",Forms貼り付け!$A$3:$AZ$3,2),"") | AO3: =IFERROR(XMATCH("*Q36*",Forms貼り付け!$A$3:$AZ$3,2),"") | AP3: =IFERROR(XMATCH("*Q37*",Forms貼り付け!$A$3:$AZ$3,2),"") | AQ3: =IFERROR(XMATCH("*Q38*",Forms貼り付け!$A$3:$AZ$3,2),"") | AR3: =IFERROR(XMATCH("*Q39*",Forms貼り付け!$A$3:$AZ$3,2),"") | AS3: =IFERROR(XMATCH("*Q40*",Forms貼り付け!$A$3:$AZ$3,2),"") | AT3: =IFERROR(XMATCH("*Q41*",Forms貼り付け!$A$3:$AZ$3,2),"") | AU3: =IFERROR(XMATCH("*Q42*",Forms貼り付け!$A$3:$AZ$3,2),"") | AV3: =IFERROR(XMATCH("*Q43*",Forms貼り付け!$A$3:$AZ$3,2),"") | AW3: =IFERROR(XMATCH("*Q44*",Forms貼り付け!$A$3:$AZ$3,2),"") | AX3: =IFERROR(XMATCH("*Q45*",Forms貼り付け!$A$3:$AZ$3,2),"") | AY3: =IFERROR(XMATCH("*Q46*",Forms貼り付け!$A$3:$AZ$3,2),"") | AZ3: =IFERROR(XMATCH("*Q47*",Forms貼り付け!$A$3:$AZ$3,2),"") | BA3: =IFERROR(XMATCH("*Q48*",Forms貼り付け!$A$3:$AZ$3,2),"") | BB3: =IFERROR(XMATCH("*Q49*",Forms貼り付け!$A$3:$AZ$3,2),"") | BC3: =IFERROR(XMATCH("*Q50*",Forms貼り付け!$A$3:$AZ$3,2),"")
A4: 受験者ID | B4: 氏名 | C4: メール | D4: 開始時刻 | E4: 完了時刻 | F4: Q1 | G4: Q2 | H4: Q3 | I4: Q4 | J4: Q5 | K4: Q6 | L4: Q7 | M4: Q8 | N4: Q9 | O4: Q10 | P4: Q11 | Q4: Q12 | R4: Q13 | S4: Q14 | T4: Q15 | U4: Q16 | V4: Q17 | W4: Q18 | X4: Q19 | Y4: Q20 | Z4: Q21 | AA4: Q22 | AB4: Q23 | AC4: Q24 | AD4: Q25 | AE4: Q26 | AF4: Q27 | AG4: Q28 | AH4: Q29 | AI4: Q30 | AJ4: Q31 | AK4: Q32 | AL4: Q33 | AM4: Q34 | AN4: Q35 | AO4: Q36 | AP4: Q37 | AQ4: Q38 | AR4: Q39 | AS4: Q40 | AT4: Q41 | AU4: Q42 | AV4: Q43 | AW4: Q44 | AX4: Q45 | AY4: Q46 | AZ4: Q47 | BA4: Q48 | BB4: Q49 | BC4: Q50
A5: U001 | B5: =IF($B$3="","",INDEX(Forms貼り付け!$A:$AZ,4,$B$3)) | C5: =IF($C$3="","",INDEX(Forms貼り付け!$A:$AZ,4,$C$3)) | D5: =IF($D$3="","",INDEX(Forms貼り付け!$A:$AZ,4,$D$3)) | E5: =IF($E$3="","",INDEX(Forms貼り付け!$A:$AZ,4,$E$3)) | F5: =IF(F$3="","",IFERROR(LEFT(TRIM(INDEX(Forms貼り付け!$A:$AZ,4,F$3)),1),"")) | G5: =IF(G$3="","",IFERROR(LEFT(TRIM(INDEX(Forms貼り付け!$A:$AZ,4,G$3)),1),"")) | H5: =IF(H$3="","",IFERROR(LEFT(TRIM(INDEX(Forms貼り付け!$A:$AZ,4,H$3)),1),"")) | I5: =IF(I$3="","",IFERROR(LEFT(TRIM(INDEX(Forms貼り付け!$A:$AZ,4,I$3)),1),"")) | J5: =IF(J$3="","",IFERROR(LEFT(TRIM(INDEX(Forms貼り付け!$A:$AZ,4,J$3)),1),"")) | K5: =IF(K$3="","",IFERROR(LEFT(TRIM(INDEX(Forms貼り付け!$A:$AZ,4,K$3)),1),"")) | L5: =IF(L$3="","",IFERROR(LEFT(TRIM(INDEX(Forms貼り付け!$A:$AZ,4,L$3)),1),"")) | M5: =IF(M$3="","",IFERROR(LEFT(TRIM(INDEX(Forms貼り付け!$A:$AZ,4,M$3)),1),"")) | ... BC5: =IF(BC$3="","",IFERROR(LEFT(TRIM(INDEX(Forms貼り付け!$A:$AZ,4,BC$3)),1),""))
A6: U002 | B6: =IF($B$3="","",INDEX(Forms貼り付け!$A:$AZ,5,$B$3)) | C6: =IF($C$3="","",INDEX(Forms貼り付け!$A:$AZ,5,$C$3)) | D6: =IF($D$3="","",INDEX(Forms貼り付け!$A:$AZ,5,$D$3)) | E6: =IF($E$3="","",INDEX(Forms貼り付け!$A:$AZ,5,$E$3)) | F6: =IF(F$3="","",IFERROR(LEFT(TRIM(INDEX(Forms貼り付け!$A:$AZ,5,F$3)),1),"")) | G6: =IF(G$3="","",IFERROR(LEFT(TRIM(INDEX(Forms貼り付け!$A:$AZ,5,G$3)),1),"")) | H6: =IF(H$3="","",IFERROR(LEFT(TRIM(INDEX(Forms貼り付け!$A:$AZ,5,H$3)),1),"")) | I6: =IF(I$3="","",IFERROR(LEFT(TRIM(INDEX(Forms貼り付け!$A:$AZ,5,I$3)),1),"")) | J6: =IF(J$3="","",IFERROR(LEFT(TRIM(INDEX(Forms貼り付け!$A:$AZ,5,J$3)),1),"")) | K6: =IF(K$3="","",IFERROR(LEFT(TRIM(INDEX(Forms貼り付け!$A:$AZ,5,K$3)),1),"")) | L6: =IF(L$3="","",IFERROR(LEFT(TRIM(INDEX(Forms貼り付け!$A:$AZ,5,L$3)),1),"")) | M6: =IF(M$3="","",IFERROR(LEFT(TRIM(INDEX(Forms貼り付け!$A:$AZ,5,M$3)),1),"")) | ... BC6: =IF(BC$3="","",IFERROR(LEFT(TRIM(INDEX(Forms貼り付け!$A:$AZ,5,BC$3)),1),""))
A7: U003 | B7: =IF($B$3="","",INDEX(Forms貼り付け!$A:$AZ,6,$B$3)) | C7: =IF($C$3="","",INDEX(Forms貼り付け!$A:$AZ,6,$C$3)) | D7: =IF($D$3="","",INDEX(Forms貼り付け!$A:$AZ,6,$D$3)) | E7: =IF($E$3="","",INDEX(Forms貼り付け!$A:$AZ,6,$E$3)) | F7: =IF(F$3="","",IFERROR(LEFT(TRIM(INDEX(Forms貼り付け!$A:$AZ,6,F$3)),1),"")) | G7: =IF(G$3="","",IFERROR(LEFT(TRIM(INDEX(Forms貼り付け!$A:$AZ,6,G$3)),1),"")) | H7: =IF(H$3="","",IFERROR(LEFT(TRIM(INDEX(Forms貼り付け!$A:$AZ,6,H$3)),1),"")) | I7: =IF(I$3="","",IFERROR(LEFT(TRIM(INDEX(Forms貼り付け!$A:$AZ,6,I$3)),1),"")) | J7: =IF(J$3="","",IFERROR(LEFT(TRIM(INDEX(Forms貼り付け!$A:$AZ,6,J$3)),1),"")) | K7: =IF(K$3="","",IFERROR(LEFT(TRIM(INDEX(Forms貼り付け!$A:$AZ,6,K$3)),1),"")) | L7: =IF(L$3="","",IFERROR(LEFT(TRIM(INDEX(Forms貼り付け!$A:$AZ,6,L$3)),1),"")) | M7: =IF(M$3="","",IFERROR(LEFT(TRIM(INDEX(Forms貼り付け!$A:$AZ,6,M$3)),1),"")) | ... BC7: =IF(BC$3="","",IFERROR(LEFT(TRIM(INDEX(Forms貼り付け!$A:$AZ,6,BC$3)),1),""))
A8: U004 | B8: =IF($B$3="","",INDEX(Forms貼り付け!$A:$AZ,7,$B$3)) | C8: =IF($C$3="","",INDEX(Forms貼り付け!$A:$AZ,7,$C$3)) | D8: =IF($D$3="","",INDEX(Forms貼り付け!$A:$AZ,7,$D$3)) | E8: =IF($E$3="","",INDEX(Forms貼り付け!$A:$AZ,7,$E$3)) | F8: =IF(F$3="","",IFERROR(LEFT(TRIM(INDEX(Forms貼り付け!$A:$AZ,7,F$3)),1),"")) | G8: =IF(G$3="","",IFERROR(LEFT(TRIM(INDEX(Forms貼り付け!$A:$AZ,7,G$3)),1),"")) | H8: =IF(H$3="","",IFERROR(LEFT(TRIM(INDEX(Forms貼り付け!$A:$AZ,7,H$3)),1),"")) | I8: =IF(I$3="","",IFERROR(LEFT(TRIM(INDEX(Forms貼り付け!$A:$AZ,7,I$3)),1),"")) | J8: =IF(J$3="","",IFERROR(LEFT(TRIM(INDEX(Forms貼り付け!$A:$AZ,7,J$3)),1),"")) | K8: =IF(K$3="","",IFERROR(LEFT(TRIM(INDEX(Forms貼り付け!$A:$AZ,7,K$3)),1),"")) | L8: =IF(L$3="","",IFERROR(LEFT(TRIM(INDEX(Forms貼り付け!$A:$AZ,7,L$3)),1),"")) | M8: =IF(M$3="","",IFERROR(LEFT(TRIM(INDEX(Forms貼り付け!$A:$AZ,7,M$3)),1),"")) | ... BC8: =IF(BC$3="","",IFERROR(LEFT(TRIM(INDEX(Forms貼り付け!$A:$AZ,7,BC$3)),1),""))
A9: U005 | B9: =IF($B$3="","",INDEX(Forms貼り付け!$A:$AZ,8,$B$3)) | C9: =IF($C$3="","",INDEX(Forms貼り付け!$A:$AZ,8,$C$3)) | D9: =IF($D$3="","",INDEX(Forms貼り付け!$A:$AZ,8,$D$3)) | E9: =IF($E$3="","",INDEX(Forms貼り付け!$A:$AZ,8,$E$3)) | F9: =IF(F$3="","",IFERROR(LEFT(TRIM(INDEX(Forms貼り付け!$A:$AZ,8,F$3)),1),"")) | G9: =IF(G$3="","",IFERROR(LEFT(TRIM(INDEX(Forms貼り付け!$A:$AZ,8,G$3)),1),"")) | H9: =IF(H$3="","",IFERROR(LEFT(TRIM(INDEX(Forms貼り付け!$A:$AZ,8,H$3)),1),"")) | I9: =IF(I$3="","",IFERROR(LEFT(TRIM(INDEX(Forms貼り付け!$A:$AZ,8,I$3)),1),"")) | J9: =IF(J$3="","",IFERROR(LEFT(TRIM(INDEX(Forms貼り付け!$A:$AZ,8,J$3)),1),"")) | K9: =IF(K$3="","",IFERROR(LEFT(TRIM(INDEX(Forms貼り付け!$A:$AZ,8,K$3)),1),"")) | L9: =IF(L$3="","",IFERROR(LEFT(TRIM(INDEX(Forms貼り付け!$A:$AZ,8,L$3)),1),"")) | M9: =IF(M$3="","",IFERROR(LEFT(TRIM(INDEX(Forms貼り付け!$A:$AZ,8,M$3)),1),"")) | ... BC9: =IF(BC$3="","",IFERROR(LEFT(TRIM(INDEX(Forms貼り付け!$A:$AZ,8,BC$3)),1),""))
A10: U006 | B10: =IF($B$3="","",INDEX(Forms貼り付け!$A:$AZ,9,$B$3)) | C10: =IF($C$3="","",INDEX(Forms貼り付け!$A:$AZ,9,$C$3)) | D10: =IF($D$3="","",INDEX(Forms貼り付け!$A:$AZ,9,$D$3)) | E10: =IF($E$3="","",INDEX(Forms貼り付け!$A:$AZ,9,$E$3)) | F10: =IF(F$3="","",IFERROR(LEFT(TRIM(INDEX(Forms貼り付け!$A:$AZ,9,F$3)),1),"")) | G10: =IF(G$3="","",IFERROR(LEFT(TRIM(INDEX(Forms貼り付け!$A:$AZ,9,G$3)),1),"")) | H10: =IF(H$3="","",IFERROR(LEFT(TRIM(INDEX(Forms貼り付け!$A:$AZ,9,H$3)),1),"")) | I10: =IF(I$3="","",IFERROR(LEFT(TRIM(INDEX(Forms貼り付け!$A:$AZ,9,I$3)),1),"")) | J10: =IF(J$3="","",IFERROR(LEFT(TRIM(INDEX(Forms貼り付け!$A:$AZ,9,J$3)),1),"")) | K10: =IF(K$3="","",IFERROR(LEFT(TRIM(INDEX(Forms貼り付け!$A:$AZ,9,K$3)),1),"")) | L10: =IF(L$3="","",IFERROR(LEFT(TRIM(INDEX(Forms貼り付け!$A:$AZ,9,L$3)),1),"")) | M10: =IF(M$3="","",IFERROR(LEFT(TRIM(INDEX(Forms貼り付け!$A:$AZ,9,M$3)),1),"")) | ... BC10: =IF(BC$3="","",IFERROR(LEFT(TRIM(INDEX(Forms貼り付け!$A:$AZ,9,BC$3)),1),""))
A11: U007 | B11: =IF($B$3="","",INDEX(Forms貼り付け!$A:$AZ,10,$B$3)) | C11: =IF($C$3="","",INDEX(Forms貼り付け!$A:$AZ,10,$C$3)) | D11: =IF($D$3="","",INDEX(Forms貼り付け!$A:$AZ,10,$D$3)) | E11: =IF($E$3="","",INDEX(Forms貼り付け!$A:$AZ,10,$E$3)) | F11: =IF(F$3="","",IFERROR(LEFT(TRIM(INDEX(Forms貼り付け!$A:$AZ,10,F$3)),1),"")) | G11: =IF(G$3="","",IFERROR(LEFT(TRIM(INDEX(Forms貼り付け!$A:$AZ,10,G$3)),1),"")) | H11: =IF(H$3="","",IFERROR(LEFT(TRIM(INDEX(Forms貼り付け!$A:$AZ,10,H$3)),1),"")) | I11: =IF(I$3="","",IFERROR(LEFT(TRIM(INDEX(Forms貼り付け!$A:$AZ,10,I$3)),1),"")) | J11: =IF(J$3="","",IFERROR(LEFT(TRIM(INDEX(Forms貼り付け!$A:$AZ,10,J$3)),1),"")) | K11: =IF(K$3="","",IFERROR(LEFT(TRIM(INDEX(Forms貼り付け!$A:$AZ,10,K$3)),1),"")) | L11: =IF(L$3="","",IFERROR(LEFT(TRIM(INDEX(Forms貼り付け!$A:$AZ,10,L$3)),1),"")) | M11: =IF(M$3="","",IFERROR(LEFT(TRIM(INDEX(Forms貼り付け!$A:$AZ,10,M$3)),1),"")) | ... BC11: =IF(BC$3="","",IFERROR(LEFT(TRIM(INDEX(Forms貼り付け!$A:$AZ,10,BC$3)),1),""))
A12: U008 | B12: =IF($B$3="","",INDEX(Forms貼り付け!$A:$AZ,11,$B$3)) | C12: =IF($C$3="","",INDEX(Forms貼り付け!$A:$AZ,11,$C$3)) | D12: =IF($D$3="","",INDEX(Forms貼り付け!$A:$AZ,11,$D$3)) | E12: =IF($E$3="","",INDEX(Forms貼り付け!$A:$AZ,11,$E$3)) | F12: =IF(F$3="","",IFERROR(LEFT(TRIM(INDEX(Forms貼り付け!$A:$AZ,11,F$3)),1),"")) | G12: =IF(G$3="","",IFERROR(LEFT(TRIM(INDEX(Forms貼り付け!$A:$AZ,11,G$3)),1),"")) | H12: =IF(H$3="","",IFERROR(LEFT(TRIM(INDEX(Forms貼り付け!$A:$AZ,11,H$3)),1),"")) | I12: =IF(I$3="","",IFERROR(LEFT(TRIM(INDEX(Forms貼り付け!$A:$AZ,11,I$3)),1),"")) | J12: =IF(J$3="","",IFERROR(LEFT(TRIM(INDEX(Forms貼り付け!$A:$AZ,11,J$3)),1),"")) | K12: =IF(K$3="","",IFERROR(LEFT(TRIM(INDEX(Forms貼り付け!$A:$AZ,11,K$3)),1),"")) | L12: =IF(L$3="","",IFERROR(LEFT(TRIM(INDEX(Forms貼り付け!$A:$AZ,11,L$3)),1),"")) | M12: =IF(M$3="","",IFERROR(LEFT(TRIM(INDEX(Forms貼り付け!$A:$AZ,11,M$3)),1),"")) | ... BC12: =IF(BC$3="","",IFERROR(LEFT(TRIM(INDEX(Forms貼り付け!$A:$AZ,11,BC$3)),1),""))
A13: U009 | B13: =IF($B$3="","",INDEX(Forms貼り付け!$A:$AZ,12,$B$3)) | C13: =IF($C$3="","",INDEX(Forms貼り付け!$A:$AZ,12,$C$3)) | D13: =IF($D$3="","",INDEX(Forms貼り付け!$A:$AZ,12,$D$3)) | E13: =IF($E$3="","",INDEX(Forms貼り付け!$A:$AZ,12,$E$3)) | F13: =IF(F$3="","",IFERROR(LEFT(TRIM(INDEX(Forms貼り付け!$A:$AZ,12,F$3)),1),"")) | G13: =IF(G$3="","",IFERROR(LEFT(TRIM(INDEX(Forms貼り付け!$A:$AZ,12,G$3)),1),"")) | H13: =IF(H$3="","",IFERROR(LEFT(TRIM(INDEX(Forms貼り付け!$A:$AZ,12,H$3)),1),"")) | I13: =IF(I$3="","",IFERROR(LEFT(TRIM(INDEX(Forms貼り付け!$A:$AZ,12,I$3)),1),"")) | J13: =IF(J$3="","",IFERROR(LEFT(TRIM(INDEX(Forms貼り付け!$A:$AZ,12,J$3)),1),"")) | K13: =IF(K$3="","",IFERROR(LEFT(TRIM(INDEX(Forms貼り付け!$A:$AZ,12,K$3)),1),"")) | L13: =IF(L$3="","",IFERROR(LEFT(TRIM(INDEX(Forms貼り付け!$A:$AZ,12,L$3)),1),"")) | M13: =IF(M$3="","",IFERROR(LEFT(TRIM(INDEX(Forms貼り付け!$A:$AZ,12,M$3)),1),"")) | ... BC13: =IF(BC$3="","",IFERROR(LEFT(TRIM(INDEX(Forms貼り付け!$A:$AZ,12,BC$3)),1),""))
A14: U010 | B14: =IF($B$3="","",INDEX(Forms貼り付け!$A:$AZ,13,$B$3)) | C14: =IF($C$3="","",INDEX(Forms貼り付け!$A:$AZ,13,$C$3)) | D14: =IF($D$3="","",INDEX(Forms貼り付け!$A:$AZ,13,$D$3)) | E14: =IF($E$3="","",INDEX(Forms貼り付け!$A:$AZ,13,$E$3)) | F14: =IF(F$3="","",IFERROR(LEFT(TRIM(INDEX(Forms貼り付け!$A:$AZ,13,F$3)),1),"")) | G14: =IF(G$3="","",IFERROR(LEFT(TRIM(INDEX(Forms貼り付け!$A:$AZ,13,G$3)),1),"")) | H14: =IF(H$3="","",IFERROR(LEFT(TRIM(INDEX(Forms貼り付け!$A:$AZ,13,H$3)),1),"")) | I14: =IF(I$3="","",IFERROR(LEFT(TRIM(INDEX(Forms貼り付け!$A:$AZ,13,I$3)),1),"")) | J14: =IF(J$3="","",IFERROR(LEFT(TRIM(INDEX(Forms貼り付け!$A:$AZ,13,J$3)),1),"")) | K14: =IF(K$3="","",IFERROR(LEFT(TRIM(INDEX(Forms貼り付け!$A:$AZ,13,K$3)),1),"")) | L14: =IF(L$3="","",IFERROR(LEFT(TRIM(INDEX(Forms貼り付け!$A:$AZ,13,L$3)),1),"")) | M14: =IF(M$3="","",IFERROR(LEFT(TRIM(INDEX(Forms貼り付け!$A:$AZ,13,M$3)),1),"")) | ... BC14: =IF(BC$3="","",IFERROR(LEFT(TRIM(INDEX(Forms貼り付け!$A:$AZ,13,BC$3)),1),""))
A15: U011 | B15: =IF($B$3="","",INDEX(Forms貼り付け!$A:$AZ,14,$B$3)) | C15: =IF($C$3="","",INDEX(Forms貼り付け!$A:$AZ,14,$C$3)) | D15: =IF($D$3="","",INDEX(Forms貼り付け!$A:$AZ,14,$D$3)) | E15: =IF($E$3="","",INDEX(Forms貼り付け!$A:$AZ,14,$E$3)) | F15: =IF(F$3="","",IFERROR(LEFT(TRIM(INDEX(Forms貼り付け!$A:$AZ,14,F$3)),1),"")) | G15: =IF(G$3="","",IFERROR(LEFT(TRIM(INDEX(Forms貼り付け!$A:$AZ,14,G$3)),1),"")) | H15: =IF(H$3="","",IFERROR(LEFT(TRIM(INDEX(Forms貼り付け!$A:$AZ,14,H$3)),1),"")) | I15: =IF(I$3="","",IFERROR(LEFT(TRIM(INDEX(Forms貼り付け!$A:$AZ,14,I$3)),1),"")) | J15: =IF(J$3="","",IFERROR(LEFT(TRIM(INDEX(Forms貼り付け!$A:$AZ,14,J$3)),1),"")) | K15: =IF(K$3="","",IFERROR(LEFT(TRIM(INDEX(Forms貼り付け!$A:$AZ,14,K$3)),1),"")) | L15: =IF(L$3="","",IFERROR(LEFT(TRIM(INDEX(Forms貼り付け!$A:$AZ,14,L$3)),1),"")) | M15: =IF(M$3="","",IFERROR(LEFT(TRIM(INDEX(Forms貼り付け!$A:$AZ,14,M$3)),1),"")) | ... BC15: =IF(BC$3="","",IFERROR(LEFT(TRIM(INDEX(Forms貼り付け!$A:$AZ,14,BC$3)),1),""))
A16: U012 | B16: =IF($B$3="","",INDEX(Forms貼り付け!$A:$AZ,15,$B$3)) | C16: =IF($C$3="","",INDEX(Forms貼り付け!$A:$AZ,15,$C$3)) | D16: =IF($D$3="","",INDEX(Forms貼り付け!$A:$AZ,15,$D$3)) | E16: =IF($E$3="","",INDEX(Forms貼り付け!$A:$AZ,15,$E$3)) | F16: =IF(F$3="","",IFERROR(LEFT(TRIM(INDEX(Forms貼り付け!$A:$AZ,15,F$3)),1),"")) | G16: =IF(G$3="","",IFERROR(LEFT(TRIM(INDEX(Forms貼り付け!$A:$AZ,15,G$3)),1),"")) | H16: =IF(H$3="","",IFERROR(LEFT(TRIM(INDEX(Forms貼り付け!$A:$AZ,15,H$3)),1),"")) | I16: =IF(I$3="","",IFERROR(LEFT(TRIM(INDEX(Forms貼り付け!$A:$AZ,15,I$3)),1),"")) | J16: =IF(J$3="","",IFERROR(LEFT(TRIM(INDEX(Forms貼り付け!$A:$AZ,15,J$3)),1),"")) | K16: =IF(K$3="","",IFERROR(LEFT(TRIM(INDEX(Forms貼り付け!$A:$AZ,15,K$3)),1),"")) | L16: =IF(L$3="","",IFERROR(LEFT(TRIM(INDEX(Forms貼り付け!$A:$AZ,15,L$3)),1),"")) | M16: =IF(M$3="","",IFERROR(LEFT(TRIM(INDEX(Forms貼り付け!$A:$AZ,15,M$3)),1),"")) | ... BC16: =IF(BC$3="","",IFERROR(LEFT(TRIM(INDEX(Forms貼り付け!$A:$AZ,15,BC$3)),1),""))
A17: U013 | B17: =IF($B$3="","",INDEX(Forms貼り付け!$A:$AZ,16,$B$3)) | C17: =IF($C$3="","",INDEX(Forms貼り付け!$A:$AZ,16,$C$3)) | D17: =IF($D$3="","",INDEX(Forms貼り付け!$A:$AZ,16,$D$3)) | E17: =IF($E$3="","",INDEX(Forms貼り付け!$A:$AZ,16,$E$3)) | F17: =IF(F$3="","",IFERROR(LEFT(TRIM(INDEX(Forms貼り付け!$A:$AZ,16,F$3)),1),"")) | G17: =IF(G$3="","",IFERROR(LEFT(TRIM(INDEX(Forms貼り付け!$A:$AZ,16,G$3)),1),"")) | H17: =IF(H$3="","",IFERROR(LEFT(TRIM(INDEX(Forms貼り付け!$A:$AZ,16,H$3)),1),"")) | I17: =IF(I$3="","",IFERROR(LEFT(TRIM(INDEX(Forms貼り付け!$A:$AZ,16,I$3)),1),"")) | J17: =IF(J$3="","",IFERROR(LEFT(TRIM(INDEX(Forms貼り付け!$A:$AZ,16,J$3)),1),"")) | K17: =IF(K$3="","",IFERROR(LEFT(TRIM(INDEX(Forms貼り付け!$A:$AZ,16,K$3)),1),"")) | L17: =IF(L$3="","",IFERROR(LEFT(TRIM(INDEX(Forms貼り付け!$A:$AZ,16,L$3)),1),"")) | M17: =IF(M$3="","",IFERROR(LEFT(TRIM(INDEX(Forms貼り付け!$A:$AZ,16,M$3)),1),"")) | ... BC17: =IF(BC$3="","",IFERROR(LEFT(TRIM(INDEX(Forms貼り付け!$A:$AZ,16,BC$3)),1),""))
A18: U014 | B18: =IF($B$3="","",INDEX(Forms貼り付け!$A:$AZ,17,$B$3)) | C18: =IF($C$3="","",INDEX(Forms貼り付け!$A:$AZ,17,$C$3)) | D18: =IF($D$3="","",INDEX(Forms貼り付け!$A:$AZ,17,$D$3)) | E18: =IF($E$3="","",INDEX(Forms貼り付け!$A:$AZ,17,$E$3)) | F18: =IF(F$3="","",IFERROR(LEFT(TRIM(INDEX(Forms貼り付け!$A:$AZ,17,F$3)),1),"")) | G18: =IF(G$3="","",IFERROR(LEFT(TRIM(INDEX(Forms貼り付け!$A:$AZ,17,G$3)),1),"")) | H18: =IF(H$3="","",IFERROR(LEFT(TRIM(INDEX(Forms貼り付け!$A:$AZ,17,H$3)),1),"")) | I18: =IF(I$3="","",IFERROR(LEFT(TRIM(INDEX(Forms貼り付け!$A:$AZ,17,I$3)),1),"")) | J18: =IF(J$3="","",IFERROR(LEFT(TRIM(INDEX(Forms貼り付け!$A:$AZ,17,J$3)),1),"")) | K18: =IF(K$3="","",IFERROR(LEFT(TRIM(INDEX(Forms貼り付け!$A:$AZ,17,K$3)),1),"")) | L18: =IF(L$3="","",IFERROR(LEFT(TRIM(INDEX(Forms貼り付け!$A:$AZ,17,L$3)),1),"")) | M18: =IF(M$3="","",IFERROR(LEFT(TRIM(INDEX(Forms貼り付け!$A:$AZ,17,M$3)),1),"")) | ... BC18: =IF(BC$3="","",IFERROR(LEFT(TRIM(INDEX(Forms貼り付け!$A:$AZ,17,BC$3)),1),""))
A19: U015 | B19: =IF($B$3="","",INDEX(Forms貼り付け!$A:$AZ,18,$B$3)) | C19: =IF($C$3="","",INDEX(Forms貼り付け!$A:$AZ,18,$C$3)) | D19: =IF($D$3="","",INDEX(Forms貼り付け!$A:$AZ,18,$D$3)) | E19: =IF($E$3="","",INDEX(Forms貼り付け!$A:$AZ,18,$E$3)) | F19: =IF(F$3="","",IFERROR(LEFT(TRIM(INDEX(Forms貼り付け!$A:$AZ,18,F$3)),1),"")) | G19: =IF(G$3="","",IFERROR(LEFT(TRIM(INDEX(Forms貼り付け!$A:$AZ,18,G$3)),1),"")) | H19: =IF(H$3="","",IFERROR(LEFT(TRIM(INDEX(Forms貼り付け!$A:$AZ,18,H$3)),1),"")) | I19: =IF(I$3="","",IFERROR(LEFT(TRIM(INDEX(Forms貼り付け!$A:$AZ,18,I$3)),1),"")) | J19: =IF(J$3="","",IFERROR(LEFT(TRIM(INDEX(Forms貼り付け!$A:$AZ,18,J$3)),1),"")) | K19: =IF(K$3="","",IFERROR(LEFT(TRIM(INDEX(Forms貼り付け!$A:$AZ,18,K$3)),1),"")) | L19: =IF(L$3="","",IFERROR(LEFT(TRIM(INDEX(Forms貼り付け!$A:$AZ,18,L$3)),1),"")) | M19: =IF(M$3="","",IFERROR(LEFT(TRIM(INDEX(Forms貼り付け!$A:$AZ,18,M$3)),1),"")) | ... BC19: =IF(BC$3="","",IFERROR(LEFT(TRIM(INDEX(Forms貼り付け!$A:$AZ,18,BC$3)),1),""))
A20: U016 | B20: =IF($B$3="","",INDEX(Forms貼り付け!$A:$AZ,19,$B$3)) | C20: =IF($C$3="","",INDEX(Forms貼り付け!$A:$AZ,19,$C$3)) | D20: =IF($D$3="","",INDEX(Forms貼り付け!$A:$AZ,19,$D$3)) | E20: =IF($E$3="","",INDEX(Forms貼り付け!$A:$AZ,19,$E$3)) | F20: =IF(F$3="","",IFERROR(LEFT(TRIM(INDEX(Forms貼り付け!$A:$AZ,19,F$3)),1),"")) | G20: =IF(G$3="","",IFERROR(LEFT(TRIM(INDEX(Forms貼り付け!$A:$AZ,19,G$3)),1),"")) | H20: =IF(H$3="","",IFERROR(LEFT(TRIM(INDEX(Forms貼り付け!$A:$AZ,19,H$3)),1),"")) | I20: =IF(I$3="","",IFERROR(LEFT(TRIM(INDEX(Forms貼り付け!$A:$AZ,19,I$3)),1),"")) | J20: =IF(J$3="","",IFERROR(LEFT(TRIM(INDEX(Forms貼り付け!$A:$AZ,19,J$3)),1),"")) | K20: =IF(K$3="","",IFERROR(LEFT(TRIM(INDEX(Forms貼り付け!$A:$AZ,19,K$3)),1),"")) | L20: =IF(L$3="","",IFERROR(LEFT(TRIM(INDEX(Forms貼り付け!$A:$AZ,19,L$3)),1),"")) | M20: =IF(M$3="","",IFERROR(LEFT(TRIM(INDEX(Forms貼り付け!$A:$AZ,19,M$3)),1),"")) | ... BC20: =IF(BC$3="","",IFERROR(LEFT(TRIM(INDEX(Forms貼り付け!$A:$AZ,19,BC$3)),1),""))
A21: U017 | B21: =IF($B$3="","",INDEX(Forms貼り付け!$A:$AZ,20,$B$3)) | C21: =IF($C$3="","",INDEX(Forms貼り付け!$A:$AZ,20,$C$3)) | D21: =IF($D$3="","",INDEX(Forms貼り付け!$A:$AZ,20,$D$3)) | E21: =IF($E$3="","",INDEX(Forms貼り付け!$A:$AZ,20,$E$3)) | F21: =IF(F$3="","",IFERROR(LEFT(TRIM(INDEX(Forms貼り付け!$A:$AZ,20,F$3)),1),"")) | G21: =IF(G$3="","",IFERROR(LEFT(TRIM(INDEX(Forms貼り付け!$A:$AZ,20,G$3)),1),"")) | H21: =IF(H$3="","",IFERROR(LEFT(TRIM(INDEX(Forms貼り付け!$A:$AZ,20,H$3)),1),"")) | I21: =IF(I$3="","",IFERROR(LEFT(TRIM(INDEX(Forms貼り付け!$A:$AZ,20,I$3)),1),"")) | J21: =IF(J$3="","",IFERROR(LEFT(TRIM(INDEX(Forms貼り付け!$A:$AZ,20,J$3)),1),"")) | K21: =IF(K$3="","",IFERROR(LEFT(TRIM(INDEX(Forms貼り付け!$A:$AZ,20,K$3)),1),"")) | L21: =IF(L$3="","",IFERROR(LEFT(TRIM(INDEX(Forms貼り付け!$A:$AZ,20,L$3)),1),"")) | M21: =IF(M$3="","",IFERROR(LEFT(TRIM(INDEX(Forms貼り付け!$A:$AZ,20,M$3)),1),"")) | ... BC21: =IF(BC$3="","",IFERROR(LEFT(TRIM(INDEX(Forms貼り付け!$A:$AZ,20,BC$3)),1),""))
A22: U018 | B22: =IF($B$3="","",INDEX(Forms貼り付け!$A:$AZ,21,$B$3)) | C22: =IF($C$3="","",INDEX(Forms貼り付け!$A:$AZ,21,$C$3)) | D22: =IF($D$3="","",INDEX(Forms貼り付け!$A:$AZ,21,$D$3)) | E22: =IF($E$3="","",INDEX(Forms貼り付け!$A:$AZ,21,$E$3)) | F22: =IF(F$3="","",IFERROR(LEFT(TRIM(INDEX(Forms貼り付け!$A:$AZ,21,F$3)),1),"")) | G22: =IF(G$3="","",IFERROR(LEFT(TRIM(INDEX(Forms貼り付け!$A:$AZ,21,G$3)),1),"")) | H22: =IF(H$3="","",IFERROR(LEFT(TRIM(INDEX(Forms貼り付け!$A:$AZ,21,H$3)),1),"")) | I22: =IF(I$3="","",IFERROR(LEFT(TRIM(INDEX(Forms貼り付け!$A:$AZ,21,I$3)),1),"")) | J22: =IF(J$3="","",IFERROR(LEFT(TRIM(INDEX(Forms貼り付け!$A:$AZ,21,J$3)),1),"")) | K22: =IF(K$3="","",IFERROR(LEFT(TRIM(INDEX(Forms貼り付け!$A:$AZ,21,K$3)),1),"")) | L22: =IF(L$3="","",IFERROR(LEFT(TRIM(INDEX(Forms貼り付け!$A:$AZ,21,L$3)),1),"")) | M22: =IF(M$3="","",IFERROR(LEFT(TRIM(INDEX(Forms貼り付け!$A:$AZ,21,M$3)),1),"")) | ... BC22: =IF(BC$3="","",IFERROR(LEFT(TRIM(INDEX(Forms貼り付け!$A:$AZ,21,BC$3)),1),""))
A23: U019 | B23: =IF($B$3="","",INDEX(Forms貼り付け!$A:$AZ,22,$B$3)) | C23: =IF($C$3="","",INDEX(Forms貼り付け!$A:$AZ,22,$C$3)) | D23: =IF($D$3="","",INDEX(Forms貼り付け!$A:$AZ,22,$D$3)) | E23: =IF($E$3="","",INDEX(Forms貼り付け!$A:$AZ,22,$E$3)) | F23: =IF(F$3="","",IFERROR(LEFT(TRIM(INDEX(Forms貼り付け!$A:$AZ,22,F$3)),1),"")) | G23: =IF(G$3="","",IFERROR(LEFT(TRIM(INDEX(Forms貼り付け!$A:$AZ,22,G$3)),1),"")) | H23: =IF(H$3="","",IFERROR(LEFT(TRIM(INDEX(Forms貼り付け!$A:$AZ,22,H$3)),1),"")) | I23: =IF(I$3="","",IFERROR(LEFT(TRIM(INDEX(Forms貼り付け!$A:$AZ,22,I$3)),1),"")) | J23: =IF(J$3="","",IFERROR(LEFT(TRIM(INDEX(Forms貼り付け!$A:$AZ,22,J$3)),1),"")) | K23: =IF(K$3="","",IFERROR(LEFT(TRIM(INDEX(Forms貼り付け!$A:$AZ,22,K$3)),1),"")) | L23: =IF(L$3="","",IFERROR(LEFT(TRIM(INDEX(Forms貼り付け!$A:$AZ,22,L$3)),1),"")) | M23: =IF(M$3="","",IFERROR(LEFT(TRIM(INDEX(Forms貼り付け!$A:$AZ,22,M$3)),1),"")) | ... BC23: =IF(BC$3="","",IFERROR(LEFT(TRIM(INDEX(Forms貼り付け!$A:$AZ,22,BC$3)),1),""))
A24: U020 | B24: =IF($B$3="","",INDEX(Forms貼り付け!$A:$AZ,23,$B$3)) | C24: =IF($C$3="","",INDEX(Forms貼り付け!$A:$AZ,23,$C$3)) | D24: =IF($D$3="","",INDEX(Forms貼り付け!$A:$AZ,23,$D$3)) | E24: =IF($E$3="","",INDEX(Forms貼り付け!$A:$AZ,23,$E$3)) | F24: =IF(F$3="","",IFERROR(LEFT(TRIM(INDEX(Forms貼り付け!$A:$AZ,23,F$3)),1),"")) | G24: =IF(G$3="","",IFERROR(LEFT(TRIM(INDEX(Forms貼り付け!$A:$AZ,23,G$3)),1),"")) | H24: =IF(H$3="","",IFERROR(LEFT(TRIM(INDEX(Forms貼り付け!$A:$AZ,23,H$3)),1),"")) | I24: =IF(I$3="","",IFERROR(LEFT(TRIM(INDEX(Forms貼り付け!$A:$AZ,23,I$3)),1),"")) | J24: =IF(J$3="","",IFERROR(LEFT(TRIM(INDEX(Forms貼り付け!$A:$AZ,23,J$3)),1),"")) | K24: =IF(K$3="","",IFERROR(LEFT(TRIM(INDEX(Forms貼り付け!$A:$AZ,23,K$3)),1),"")) | L24: =IF(L$3="","",IFERROR(LEFT(TRIM(INDEX(Forms貼り付け!$A:$AZ,23,L$3)),1),"")) | M24: =IF(M$3="","",IFERROR(LEFT(TRIM(INDEX(Forms貼り付け!$A:$AZ,23,M$3)),1),"")) | ... BC24: =IF(BC$3="","",IFERROR(LEFT(TRIM(INDEX(Forms貼り付け!$A:$AZ,23,BC$3)),1),""))
A25: U021 | B25: =IF($B$3="","",INDEX(Forms貼り付け!$A:$AZ,24,$B$3)) | C25: =IF($C$3="","",INDEX(Forms貼り付け!$A:$AZ,24,$C$3)) | D25: =IF($D$3="","",INDEX(Forms貼り付け!$A:$AZ,24,$D$3)) | E25: =IF($E$3="","",INDEX(Forms貼り付け!$A:$AZ,24,$E$3)) | F25: =IF(F$3="","",IFERROR(LEFT(TRIM(INDEX(Forms貼り付け!$A:$AZ,24,F$3)),1),"")) | G25: =IF(G$3="","",IFERROR(LEFT(TRIM(INDEX(Forms貼り付け!$A:$AZ,24,G$3)),1),"")) | H25: =IF(H$3="","",IFERROR(LEFT(TRIM(INDEX(Forms貼り付け!$A:$AZ,24,H$3)),1),"")) | I25: =IF(I$3="","",IFERROR(LEFT(TRIM(INDEX(Forms貼り付け!$A:$AZ,24,I$3)),1),"")) | J25: =IF(J$3="","",IFERROR(LEFT(TRIM(INDEX(Forms貼り付け!$A:$AZ,24,J$3)),1),"")) | K25: =IF(K$3="","",IFERROR(LEFT(TRIM(INDEX(Forms貼り付け!$A:$AZ,24,K$3)),1),"")) | L25: =IF(L$3="","",IFERROR(LEFT(TRIM(INDEX(Forms貼り付け!$A:$AZ,24,L$3)),1),"")) | M25: =IF(M$3="","",IFERROR(LEFT(TRIM(INDEX(Forms貼り付け!$A:$AZ,24,M$3)),1),"")) | ... BC25: =IF(BC$3="","",IFERROR(LEFT(TRIM(INDEX(Forms貼り付け!$A:$AZ,24,BC$3)),1),""))
A26: U022 | B26: =IF($B$3="","",INDEX(Forms貼り付け!$A:$AZ,25,$B$3)) | C26: =IF($C$3="","",INDEX(Forms貼り付け!$A:$AZ,25,$C$3)) | D26: =IF($D$3="","",INDEX(Forms貼り付け!$A:$AZ,25,$D$3)) | E26: =IF($E$3="","",INDEX(Forms貼り付け!$A:$AZ,25,$E$3)) | F26: =IF(F$3="","",IFERROR(LEFT(TRIM(INDEX(Forms貼り付け!$A:$AZ,25,F$3)),1),"")) | G26: =IF(G$3="","",IFERROR(LEFT(TRIM(INDEX(Forms貼り付け!$A:$AZ,25,G$3)),1),"")) | H26: =IF(H$3="","",IFERROR(LEFT(TRIM(INDEX(Forms貼り付け!$A:$AZ,25,H$3)),1),"")) | I26: =IF(I$3="","",IFERROR(LEFT(TRIM(INDEX(Forms貼り付け!$A:$AZ,25,I$3)),1),"")) | J26: =IF(J$3="","",IFERROR(LEFT(TRIM(INDEX(Forms貼り付け!$A:$AZ,25,J$3)),1),"")) | K26: =IF(K$3="","",IFERROR(LEFT(TRIM(INDEX(Forms貼り付け!$A:$AZ,25,K$3)),1),"")) | L26: =IF(L$3="","",IFERROR(LEFT(TRIM(INDEX(Forms貼り付け!$A:$AZ,25,L$3)),1),"")) | M26: =IF(M$3="","",IFERROR(LEFT(TRIM(INDEX(Forms貼り付け!$A:$AZ,25,M$3)),1),"")) | ... BC26: =IF(BC$3="","",IFERROR(LEFT(TRIM(INDEX(Forms貼り付け!$A:$AZ,25,BC$3)),1),""))
A27: U023 | B27: =IF($B$3="","",INDEX(Forms貼り付け!$A:$AZ,26,$B$3)) | C27: =IF($C$3="","",INDEX(Forms貼り付け!$A:$AZ,26,$C$3)) | D27: =IF($D$3="","",INDEX(Forms貼り付け!$A:$AZ,26,$D$3)) | E27: =IF($E$3="","",INDEX(Forms貼り付け!$A:$AZ,26,$E$3)) | F27: =IF(F$3="","",IFERROR(LEFT(TRIM(INDEX(Forms貼り付け!$A:$AZ,26,F$3)),1),"")) | G27: =IF(G$3="","",IFERROR(LEFT(TRIM(INDEX(Forms貼り付け!$A:$AZ,26,G$3)),1),"")) | H27: =IF(H$3="","",IFERROR(LEFT(TRIM(INDEX(Forms貼り付け!$A:$AZ,26,H$3)),1),"")) | I27: =IF(I$3="","",IFERROR(LEFT(TRIM(INDEX(Forms貼り付け!$A:$AZ,26,I$3)),1),"")) | J27: =IF(J$3="","",IFERROR(LEFT(TRIM(INDEX(Forms貼り付け!$A:$AZ,26,J$3)),1),"")) | K27: =IF(K$3="","",IFERROR(LEFT(TRIM(INDEX(Forms貼り付け!$A:$AZ,26,K$3)),1),"")) | L27: =IF(L$3="","",IFERROR(LEFT(TRIM(INDEX(Forms貼り付け!$A:$AZ,26,L$3)),1),"")) | M27: =IF(M$3="","",IFERROR(LEFT(TRIM(INDEX(Forms貼り付け!$A:$AZ,26,M$3)),1),"")) | ... BC27: =IF(BC$3="","",IFERROR(LEFT(TRIM(INDEX(Forms貼り付け!$A:$AZ,26,BC$3)),1),""))
A28: U024 | B28: =IF($B$3="","",INDEX(Forms貼り付け!$A:$AZ,27,$B$3)) | C28: =IF($C$3="","",INDEX(Forms貼り付け!$A:$AZ,27,$C$3)) | D28: =IF($D$3="","",INDEX(Forms貼り付け!$A:$AZ,27,$D$3)) | E28: =IF($E$3="","",INDEX(Forms貼り付け!$A:$AZ,27,$E$3)) | F28: =IF(F$3="","",IFERROR(LEFT(TRIM(INDEX(Forms貼り付け!$A:$AZ,27,F$3)),1),"")) | G28: =IF(G$3="","",IFERROR(LEFT(TRIM(INDEX(Forms貼り付け!$A:$AZ,27,G$3)),1),"")) | H28: =IF(H$3="","",IFERROR(LEFT(TRIM(INDEX(Forms貼り付け!$A:$AZ,27,H$3)),1),"")) | I28: =IF(I$3="","",IFERROR(LEFT(TRIM(INDEX(Forms貼り付け!$A:$AZ,27,I$3)),1),"")) | J28: =IF(J$3="","",IFERROR(LEFT(TRIM(INDEX(Forms貼り付け!$A:$AZ,27,J$3)),1),"")) | K28: =IF(K$3="","",IFERROR(LEFT(TRIM(INDEX(Forms貼り付け!$A:$AZ,27,K$3)),1),"")) | L28: =IF(L$3="","",IFERROR(LEFT(TRIM(INDEX(Forms貼り付け!$A:$AZ,27,L$3)),1),"")) | M28: =IF(M$3="","",IFERROR(LEFT(TRIM(INDEX(Forms貼り付け!$A:$AZ,27,M$3)),1),"")) | ... BC28: =IF(BC$3="","",IFERROR(LEFT(TRIM(INDEX(Forms貼り付け!$A:$AZ,27,BC$3)),1),""))
A29: U025 | B29: =IF($B$3="","",INDEX(Forms貼り付け!$A:$AZ,28,$B$3)) | C29: =IF($C$3="","",INDEX(Forms貼り付け!$A:$AZ,28,$C$3)) | D29: =IF($D$3="","",INDEX(Forms貼り付け!$A:$AZ,28,$D$3)) | E29: =IF($E$3="","",INDEX(Forms貼り付け!$A:$AZ,28,$E$3)) | F29: =IF(F$3="","",IFERROR(LEFT(TRIM(INDEX(Forms貼り付け!$A:$AZ,28,F$3)),1),"")) | G29: =IF(G$3="","",IFERROR(LEFT(TRIM(INDEX(Forms貼り付け!$A:$AZ,28,G$3)),1),"")) | H29: =IF(H$3="","",IFERROR(LEFT(TRIM(INDEX(Forms貼り付け!$A:$AZ,28,H$3)),1),"")) | I29: =IF(I$3="","",IFERROR(LEFT(TRIM(INDEX(Forms貼り付け!$A:$AZ,28,I$3)),1),"")) | J29: =IF(J$3="","",IFERROR(LEFT(TRIM(INDEX(Forms貼り付け!$A:$AZ,28,J$3)),1),"")) | K29: =IF(K$3="","",IFERROR(LEFT(TRIM(INDEX(Forms貼り付け!$A:$AZ,28,K$3)),1),"")) | L29: =IF(L$3="","",IFERROR(LEFT(TRIM(INDEX(Forms貼り付け!$A:$AZ,28,L$3)),1),"")) | M29: =IF(M$3="","",IFERROR(LEFT(TRIM(INDEX(Forms貼り付け!$A:$AZ,28,M$3)),1),"")) | ... BC29: =IF(BC$3="","",IFERROR(LEFT(TRIM(INDEX(Forms貼り付け!$A:$AZ,28,BC$3)),1),""))
A30: U026 | B30: =IF($B$3="","",INDEX(Forms貼り付け!$A:$AZ,29,$B$3)) | C30: =IF($C$3="","",INDEX(Forms貼り付け!$A:$AZ,29,$C$3)) | D30: =IF($D$3="","",INDEX(Forms貼り付け!$A:$AZ,29,$D$3)) | E30: =IF($E$3="","",INDEX(Forms貼り付け!$A:$AZ,29,$E$3)) | F30: =IF(F$3="","",IFERROR(LEFT(TRIM(INDEX(Forms貼り付け!$A:$AZ,29,F$3)),1),"")) | G30: =IF(G$3="","",IFERROR(LEFT(TRIM(INDEX(Forms貼り付け!$A:$AZ,29,G$3)),1),"")) | H30: =IF(H$3="","",IFERROR(LEFT(TRIM(INDEX(Forms貼り付け!$A:$AZ,29,H$3)),1),"")) | I30: =IF(I$3="","",IFERROR(LEFT(TRIM(INDEX(Forms貼り付け!$A:$AZ,29,I$3)),1),"")) | J30: =IF(J$3="","",IFERROR(LEFT(TRIM(INDEX(Forms貼り付け!$A:$AZ,29,J$3)),1),"")) | K30: =IF(K$3="","",IFERROR(LEFT(TRIM(INDEX(Forms貼り付け!$A:$AZ,29,K$3)),1),"")) | L30: =IF(L$3="","",IFERROR(LEFT(TRIM(INDEX(Forms貼り付け!$A:$AZ,29,L$3)),1),"")) | M30: =IF(M$3="","",IFERROR(LEFT(TRIM(INDEX(Forms貼り付け!$A:$AZ,29,M$3)),1),"")) | ... BC30: =IF(BC$3="","",IFERROR(LEFT(TRIM(INDEX(Forms貼り付け!$A:$AZ,29,BC$3)),1),""))
A31: U027 | B31: =IF($B$3="","",INDEX(Forms貼り付け!$A:$AZ,30,$B$3)) | C31: =IF($C$3="","",INDEX(Forms貼り付け!$A:$AZ,30,$C$3)) | D31: =IF($D$3="","",INDEX(Forms貼り付け!$A:$AZ,30,$D$3)) | E31: =IF($E$3="","",INDEX(Forms貼り付け!$A:$AZ,30,$E$3)) | F31: =IF(F$3="","",IFERROR(LEFT(TRIM(INDEX(Forms貼り付け!$A:$AZ,30,F$3)),1),"")) | G31: =IF(G$3="","",IFERROR(LEFT(TRIM(INDEX(Forms貼り付け!$A:$AZ,30,G$3)),1),"")) | H31: =IF(H$3="","",IFERROR(LEFT(TRIM(INDEX(Forms貼り付け!$A:$AZ,30,H$3)),1),"")) | I31: =IF(I$3="","",IFERROR(LEFT(TRIM(INDEX(Forms貼り付け!$A:$AZ,30,I$3)),1),"")) | J31: =IF(J$3="","",IFERROR(LEFT(TRIM(INDEX(Forms貼り付け!$A:$AZ,30,J$3)),1),"")) | K31: =IF(K$3="","",IFERROR(LEFT(TRIM(INDEX(Forms貼り付け!$A:$AZ,30,K$3)),1),"")) | L31: =IF(L$3="","",IFERROR(LEFT(TRIM(INDEX(Forms貼り付け!$A:$AZ,30,L$3)),1),"")) | M31: =IF(M$3="","",IFERROR(LEFT(TRIM(INDEX(Forms貼り付け!$A:$AZ,30,M$3)),1),"")) | ... BC31: =IF(BC$3="","",IFERROR(LEFT(TRIM(INDEX(Forms貼り付け!$A:$AZ,30,BC$3)),1),""))
A32: U028 | B32: =IF($B$3="","",INDEX(Forms貼り付け!$A:$AZ,31,$B$3)) | C32: =IF($C$3="","",INDEX(Forms貼り付け!$A:$AZ,31,$C$3)) | D32: =IF($D$3="","",INDEX(Forms貼り付け!$A:$AZ,31,$D$3)) | E32: =IF($E$3="","",INDEX(Forms貼り付け!$A:$AZ,31,$E$3)) | F32: =IF(F$3="","",IFERROR(LEFT(TRIM(INDEX(Forms貼り付け!$A:$AZ,31,F$3)),1),"")) | G32: =IF(G$3="","",IFERROR(LEFT(TRIM(INDEX(Forms貼り付け!$A:$AZ,31,G$3)),1),"")) | H32: =IF(H$3="","",IFERROR(LEFT(TRIM(INDEX(Forms貼り付け!$A:$AZ,31,H$3)),1),"")) | I32: =IF(I$3="","",IFERROR(LEFT(TRIM(INDEX(Forms貼り付け!$A:$AZ,31,I$3)),1),"")) | J32: =IF(J$3="","",IFERROR(LEFT(TRIM(INDEX(Forms貼り付け!$A:$AZ,31,J$3)),1),"")) | K32: =IF(K$3="","",IFERROR(LEFT(TRIM(INDEX(Forms貼り付け!$A:$AZ,31,K$3)),1),"")) | L32: =IF(L$3="","",IFERROR(LEFT(TRIM(INDEX(Forms貼り付け!$A:$AZ,31,L$3)),1),"")) | M32: =IF(M$3="","",IFERROR(LEFT(TRIM(INDEX(Forms貼り付け!$A:$AZ,31,M$3)),1),"")) | ... BC32: =IF(BC$3="","",IFERROR(LEFT(TRIM(INDEX(Forms貼り付け!$A:$AZ,31,BC$3)),1),""))
A33: U029 | B33: =IF($B$3="","",INDEX(Forms貼り付け!$A:$AZ,32,$B$3)) | C33: =IF($C$3="","",INDEX(Forms貼り付け!$A:$AZ,32,$C$3)) | D33: =IF($D$3="","",INDEX(Forms貼り付け!$A:$AZ,32,$D$3)) | E33: =IF($E$3="","",INDEX(Forms貼り付け!$A:$AZ,32,$E$3)) | F33: =IF(F$3="","",IFERROR(LEFT(TRIM(INDEX(Forms貼り付け!$A:$AZ,32,F$3)),1),"")) | G33: =IF(G$3="","",IFERROR(LEFT(TRIM(INDEX(Forms貼り付け!$A:$AZ,32,G$3)),1),"")) | H33: =IF(H$3="","",IFERROR(LEFT(TRIM(INDEX(Forms貼り付け!$A:$AZ,32,H$3)),1),"")) | I33: =IF(I$3="","",IFERROR(LEFT(TRIM(INDEX(Forms貼り付け!$A:$AZ,32,I$3)),1),"")) | J33: =IF(J$3="","",IFERROR(LEFT(TRIM(INDEX(Forms貼り付け!$A:$AZ,32,J$3)),1),"")) | K33: =IF(K$3="","",IFERROR(LEFT(TRIM(INDEX(Forms貼り付け!$A:$AZ,32,K$3)),1),"")) | L33: =IF(L$3="","",IFERROR(LEFT(TRIM(INDEX(Forms貼り付け!$A:$AZ,32,L$3)),1),"")) | M33: =IF(M$3="","",IFERROR(LEFT(TRIM(INDEX(Forms貼り付け!$A:$AZ,32,M$3)),1),"")) | ... BC33: =IF(BC$3="","",IFERROR(LEFT(TRIM(INDEX(Forms貼り付け!$A:$AZ,32,BC$3)),1),""))
A34: U030 | B34: =IF($B$3="","",INDEX(Forms貼り付け!$A:$AZ,33,$B$3)) | C34: =IF($C$3="","",INDEX(Forms貼り付け!$A:$AZ,33,$C$3)) | D34: =IF($D$3="","",INDEX(Forms貼り付け!$A:$AZ,33,$D$3)) | E34: =IF($E$3="","",INDEX(Forms貼り付け!$A:$AZ,33,$E$3)) | F34: =IF(F$3="","",IFERROR(LEFT(TRIM(INDEX(Forms貼り付け!$A:$AZ,33,F$3)),1),"")) | G34: =IF(G$3="","",IFERROR(LEFT(TRIM(INDEX(Forms貼り付け!$A:$AZ,33,G$3)),1),"")) | H34: =IF(H$3="","",IFERROR(LEFT(TRIM(INDEX(Forms貼り付け!$A:$AZ,33,H$3)),1),"")) | I34: =IF(I$3="","",IFERROR(LEFT(TRIM(INDEX(Forms貼り付け!$A:$AZ,33,I$3)),1),"")) | J34: =IF(J$3="","",IFERROR(LEFT(TRIM(INDEX(Forms貼り付け!$A:$AZ,33,J$3)),1),"")) | K34: =IF(K$3="","",IFERROR(LEFT(TRIM(INDEX(Forms貼り付け!$A:$AZ,33,K$3)),1),"")) | L34: =IF(L$3="","",IFERROR(LEFT(TRIM(INDEX(Forms貼り付け!$A:$AZ,33,L$3)),1),"")) | M34: =IF(M$3="","",IFERROR(LEFT(TRIM(INDEX(Forms貼り付け!$A:$AZ,33,M$3)),1),"")) | ... BC34: =IF(BC$3="","",IFERROR(LEFT(TRIM(INDEX(Forms貼り付け!$A:$AZ,33,BC$3)),1),""))
A35: U031 | B35: =IF($B$3="","",INDEX(Forms貼り付け!$A:$AZ,34,$B$3)) | C35: =IF($C$3="","",INDEX(Forms貼り付け!$A:$AZ,34,$C$3)) | D35: =IF($D$3="","",INDEX(Forms貼り付け!$A:$AZ,34,$D$3)) | E35: =IF($E$3="","",INDEX(Forms貼り付け!$A:$AZ,34,$E$3)) | F35: =IF(F$3="","",IFERROR(LEFT(TRIM(INDEX(Forms貼り付け!$A:$AZ,34,F$3)),1),"")) | G35: =IF(G$3="","",IFERROR(LEFT(TRIM(INDEX(Forms貼り付け!$A:$AZ,34,G$3)),1),"")) | H35: =IF(H$3="","",IFERROR(LEFT(TRIM(INDEX(Forms貼り付け!$A:$AZ,34,H$3)),1),"")) | I35: =IF(I$3="","",IFERROR(LEFT(TRIM(INDEX(Forms貼り付け!$A:$AZ,34,I$3)),1),"")) | J35: =IF(J$3="","",IFERROR(LEFT(TRIM(INDEX(Forms貼り付け!$A:$AZ,34,J$3)),1),"")) | K35: =IF(K$3="","",IFERROR(LEFT(TRIM(INDEX(Forms貼り付け!$A:$AZ,34,K$3)),1),"")) | L35: =IF(L$3="","",IFERROR(LEFT(TRIM(INDEX(Forms貼り付け!$A:$AZ,34,L$3)),1),"")) | M35: =IF(M$3="","",IFERROR(LEFT(TRIM(INDEX(Forms貼り付け!$A:$AZ,34,M$3)),1),"")) | ... BC35: =IF(BC$3="","",IFERROR(LEFT(TRIM(INDEX(Forms貼り付け!$A:$AZ,34,BC$3)),1),""))
A36: U032 | B36: =IF($B$3="","",INDEX(Forms貼り付け!$A:$AZ,35,$B$3)) | C36: =IF($C$3="","",INDEX(Forms貼り付け!$A:$AZ,35,$C$3)) | D36: =IF($D$3="","",INDEX(Forms貼り付け!$A:$AZ,35,$D$3)) | E36: =IF($E$3="","",INDEX(Forms貼り付け!$A:$AZ,35,$E$3)) | F36: =IF(F$3="","",IFERROR(LEFT(TRIM(INDEX(Forms貼り付け!$A:$AZ,35,F$3)),1),"")) | G36: =IF(G$3="","",IFERROR(LEFT(TRIM(INDEX(Forms貼り付け!$A:$AZ,35,G$3)),1),"")) | H36: =IF(H$3="","",IFERROR(LEFT(TRIM(INDEX(Forms貼り付け!$A:$AZ,35,H$3)),1),"")) | I36: =IF(I$3="","",IFERROR(LEFT(TRIM(INDEX(Forms貼り付け!$A:$AZ,35,I$3)),1),"")) | J36: =IF(J$3="","",IFERROR(LEFT(TRIM(INDEX(Forms貼り付け!$A:$AZ,35,J$3)),1),"")) | K36: =IF(K$3="","",IFERROR(LEFT(TRIM(INDEX(Forms貼り付け!$A:$AZ,35,K$3)),1),"")) | L36: =IF(L$3="","",IFERROR(LEFT(TRIM(INDEX(Forms貼り付け!$A:$AZ,35,L$3)),1),"")) | M36: =IF(M$3="","",IFERROR(LEFT(TRIM(INDEX(Forms貼り付け!$A:$AZ,35,M$3)),1),"")) | ... BC36: =IF(BC$3="","",IFERROR(LEFT(TRIM(INDEX(Forms貼り付け!$A:$AZ,35,BC$3)),1),""))
A37: U033 | B37: =IF($B$3="","",INDEX(Forms貼り付け!$A:$AZ,36,$B$3)) | C37: =IF($C$3="","",INDEX(Forms貼り付け!$A:$AZ,36,$C$3)) | D37: =IF($D$3="","",INDEX(Forms貼り付け!$A:$AZ,36,$D$3)) | E37: =IF($E$3="","",INDEX(Forms貼り付け!$A:$AZ,36,$E$3)) | F37: =IF(F$3="","",IFERROR(LEFT(TRIM(INDEX(Forms貼り付け!$A:$AZ,36,F$3)),1),"")) | G37: =IF(G$3="","",IFERROR(LEFT(TRIM(INDEX(Forms貼り付け!$A:$AZ,36,G$3)),1),"")) | H37: =IF(H$3="","",IFERROR(LEFT(TRIM(INDEX(Forms貼り付け!$A:$AZ,36,H$3)),1),"")) | I37: =IF(I$3="","",IFERROR(LEFT(TRIM(INDEX(Forms貼り付け!$A:$AZ,36,I$3)),1),"")) | J37: =IF(J$3="","",IFERROR(LEFT(TRIM(INDEX(Forms貼り付け!$A:$AZ,36,J$3)),1),"")) | K37: =IF(K$3="","",IFERROR(LEFT(TRIM(INDEX(Forms貼り付け!$A:$AZ,36,K$3)),1),"")) | L37: =IF(L$3="","",IFERROR(LEFT(TRIM(INDEX(Forms貼り付け!$A:$AZ,36,L$3)),1),"")) | M37: =IF(M$3="","",IFERROR(LEFT(TRIM(INDEX(Forms貼り付け!$A:$AZ,36,M$3)),1),"")) | ... BC37: =IF(BC$3="","",IFERROR(LEFT(TRIM(INDEX(Forms貼り付け!$A:$AZ,36,BC$3)),1),""))
A38: U034 | B38: =IF($B$3="","",INDEX(Forms貼り付け!$A:$AZ,37,$B$3)) | C38: =IF($C$3="","",INDEX(Forms貼り付け!$A:$AZ,37,$C$3)) | D38: =IF($D$3="","",INDEX(Forms貼り付け!$A:$AZ,37,$D$3)) | E38: =IF($E$3="","",INDEX(Forms貼り付け!$A:$AZ,37,$E$3)) | F38: =IF(F$3="","",IFERROR(LEFT(TRIM(INDEX(Forms貼り付け!$A:$AZ,37,F$3)),1),"")) | G38: =IF(G$3="","",IFERROR(LEFT(TRIM(INDEX(Forms貼り付け!$A:$AZ,37,G$3)),1),"")) | H38: =IF(H$3="","",IFERROR(LEFT(TRIM(INDEX(Forms貼り付け!$A:$AZ,37,H$3)),1),"")) | I38: =IF(I$3="","",IFERROR(LEFT(TRIM(INDEX(Forms貼り付け!$A:$AZ,37,I$3)),1),"")) | J38: =IF(J$3="","",IFERROR(LEFT(TRIM(INDEX(Forms貼り付け!$A:$AZ,37,J$3)),1),"")) | K38: =IF(K$3="","",IFERROR(LEFT(TRIM(INDEX(Forms貼り付け!$A:$AZ,37,K$3)),1),"")) | L38: =IF(L$3="","",IFERROR(LEFT(TRIM(INDEX(Forms貼り付け!$A:$AZ,37,L$3)),1),"")) | M38: =IF(M$3="","",IFERROR(LEFT(TRIM(INDEX(Forms貼り付け!$A:$AZ,37,M$3)),1),"")) | ... BC38: =IF(BC$3="","",IFERROR(LEFT(TRIM(INDEX(Forms貼り付け!$A:$AZ,37,BC$3)),1),""))
A39: U035 | B39: =IF($B$3="","",INDEX(Forms貼り付け!$A:$AZ,38,$B$3)) | C39: =IF($C$3="","",INDEX(Forms貼り付け!$A:$AZ,38,$C$3)) | D39: =IF($D$3="","",INDEX(Forms貼り付け!$A:$AZ,38,$D$3)) | E39: =IF($E$3="","",INDEX(Forms貼り付け!$A:$AZ,38,$E$3)) | F39: =IF(F$3="","",IFERROR(LEFT(TRIM(INDEX(Forms貼り付け!$A:$AZ,38,F$3)),1),"")) | G39: =IF(G$3="","",IFERROR(LEFT(TRIM(INDEX(Forms貼り付け!$A:$AZ,38,G$3)),1),"")) | H39: =IF(H$3="","",IFERROR(LEFT(TRIM(INDEX(Forms貼り付け!$A:$AZ,38,H$3)),1),"")) | I39: =IF(I$3="","",IFERROR(LEFT(TRIM(INDEX(Forms貼り付け!$A:$AZ,38,I$3)),1),"")) | J39: =IF(J$3="","",IFERROR(LEFT(TRIM(INDEX(Forms貼り付け!$A:$AZ,38,J$3)),1),"")) | K39: =IF(K$3="","",IFERROR(LEFT(TRIM(INDEX(Forms貼り付け!$A:$AZ,38,K$3)),1),"")) | L39: =IF(L$3="","",IFERROR(LEFT(TRIM(INDEX(Forms貼り付け!$A:$AZ,38,L$3)),1),"")) | M39: =IF(M$3="","",IFERROR(LEFT(TRIM(INDEX(Forms貼り付け!$A:$AZ,38,M$3)),1),"")) | ... BC39: =IF(BC$3="","",IFERROR(LEFT(TRIM(INDEX(Forms貼り付け!$A:$AZ,38,BC$3)),1),""))
A40: U036 | B40: =IF($B$3="","",INDEX(Forms貼り付け!$A:$AZ,39,$B$3)) | C40: =IF($C$3="","",INDEX(Forms貼り付け!$A:$AZ,39,$C$3)) | D40: =IF($D$3="","",INDEX(Forms貼り付け!$A:$AZ,39,$D$3)) | E40: =IF($E$3="","",INDEX(Forms貼り付け!$A:$AZ,39,$E$3)) | F40: =IF(F$3="","",IFERROR(LEFT(TRIM(INDEX(Forms貼り付け!$A:$AZ,39,F$3)),1),"")) | G40: =IF(G$3="","",IFERROR(LEFT(TRIM(INDEX(Forms貼り付け!$A:$AZ,39,G$3)),1),"")) | H40: =IF(H$3="","",IFERROR(LEFT(TRIM(INDEX(Forms貼り付け!$A:$AZ,39,H$3)),1),"")) | I40: =IF(I$3="","",IFERROR(LEFT(TRIM(INDEX(Forms貼り付け!$A:$AZ,39,I$3)),1),"")) | J40: =IF(J$3="","",IFERROR(LEFT(TRIM(INDEX(Forms貼り付け!$A:$AZ,39,J$3)),1),"")) | K40: =IF(K$3="","",IFERROR(LEFT(TRIM(INDEX(Forms貼り付け!$A:$AZ,39,K$3)),1),"")) | L40: =IF(L$3="","",IFERROR(LEFT(TRIM(INDEX(Forms貼り付け!$A:$AZ,39,L$3)),1),"")) | M40: =IF(M$3="","",IFERROR(LEFT(TRIM(INDEX(Forms貼り付け!$A:$AZ,39,M$3)),1),"")) | ... BC40: =IF(BC$3="","",IFERROR(LEFT(TRIM(INDEX(Forms貼り付け!$A:$AZ,39,BC$3)),1),""))
...

Sheet 集計
A1: 集計（Forms貼り付け対応・自動計算）
A2: 整形回答のQ1〜Q50（A/B/C/D）を使って重み付け採点します。
A4: 受験者ID | B4: 氏名 | C4: メール | D4: 得点合計 | E4: 最大点合計 | F4: 総合(100点) | G4: OS(100点) | H4: AWS(100点) | I4: NW/Sec(100点) | J4: 判定 | K4: 完了時刻
A5: =整形回答!A5 | B5: =整形回答!B5 | C5: =整形回答!C5 | D5: =IF(B5="","",SUMPRODUCT(--(整形回答!F5:BC5=正解キー!$B$2:$B$51)*XLOOKUP(設定!$B$11:$B$60,設定!$A$5:$A$7,設定!$B$5:$B$7)*XLOOKUP(設定!$C$11:$C$60,設定!$D$5:$D$7,設定!$E$5:$E$7))) | E5: =SUMPRODUCT(XLOOKUP(設定!$B$11:$B$60,設定!$A$5:$A$7,設定!$B$5:$B$7)*XLOOKUP(設定!$C$11:$C$60,設定!$D$5:$D$7,設定!$E$5:$E$7)) | F5: =IF(D5="","",D5/E5*100) | G5: =IF(D5="","",IF(SUMPRODUCT(--(設定!$B$11:$B$60="OS（Linux/Windows）")*XLOOKUP(設定!$B$11:$B$60,設定!$A$5:$A$7,設定!$B$5:$B$7)*XLOOKUP(設定!$C$11:$C$60,設定!$D$5:$D$7,設定!$E$5:$E$7))=0,"",SUMPRODUCT(--(設定!$B$11:$B$60="OS（Linux/Windows）")*--(整形回答!F5:BC5=正解キー!$B$2:$B$51)*XLOOKUP(設定!$B$11:$B$60,設定!$A$5:$A$7,設定!$B$5:$B$7)*XLOOKUP(設定!$C$11:$C$60,設定!$D$5:$D$7,設定!$E$5:$E$7))/SUMPRODUCT(--(設定!$B$11:$B$60="OS（Linux/Windows）")*XLOOKUP(設定!$B$11:$B$60,設定!$A$5:$A$7,設定!$B$5:$B$7)*XLOOKUP(設定!$C$11:$C$60,設定!$D$5:$D$7,設定!$E$5:$E$7))*100)) | H5: =IF(D5="","",IF(SUMPRODUCT(--(設定!$B$11:$B$60="AWS")*XLOOKUP(設定!$B$11:$B$60,設定!$A$5:$A$7,設定!$B$5:$B$7)*XLOOKUP(設定!$C$11:$C$60,設定!$D$5:$D$7,設定!$E$5:$E$7))=0,"",SUMPRODUCT(--(設定!$B$11:$B$60="AWS")*--(整形回答!F5:BC5=正解キー!$B$2:$B$51)*XLOOKUP(設定!$B$11:$B$60,設定!$A$5:$A$7,設定!$B$5:$B$7)*XLOOKUP(設定!$C$11:$C$60,設定!$D$5:$D$7,設定!$E$5:$E$7))/SUMPRODUCT(--(設定!$B$11:$B$60="AWS")*XLOOKUP(設定!$B$11:$B$60,設定!$A$5:$A$7,設定!$B$5:$B$7)*XLOOKUP(設定!$C$11:$C$60,設定!$D$5:$D$7,設定!$E$5:$E$7))*100)) | I5: =IF(D5="","",IF(SUMPRODUCT(--(設定!$B$11:$B$60="NW/Security")*XLOOKUP(設定!$B$11:$B$60,設定!$A$5:$A$7,設定!$B$5:$B$7)*XLOOKUP(設定!$C$11:$C$60,設定!$D$5:$D$7,設定!$E$5:$E$7))=0,"",SUMPRODUCT(--(設定!$B$11:$B$60="NW/Security")*--(整形回答!F5:BC5=正解キー!$B$2:$B$51)*XLOOKUP(設定!$B$11:$B$60,設定!$A$5:$A$7,設定!$B$5:$B$7)*XLOOKUP(設定!$C$11:$C$60,設定!$D$5:$D$7,設定!$E$5:$E$7))/SUMPRODUCT(--(設定!$B$11:$B$60="NW/Security")*XLOOKUP(設定!$B$11:$B$60,設定!$A$5:$A$7,設定!$B$5:$B$7)*XLOOKUP(設定!$C$11:$C$60,設定!$D$5:$D$7,設定!$E$5:$E$7))*100)) | J5: =IF(F5="","",IF(F5>=85,"即戦力",IF(F5>=70,"主担当",IF(F5>=55,"サポート","育成")))) | K5: =整形回答!E5
A6: =整形回答!A6 | B6: =整形回答!B6 | C6: =整形回答!C6 | D6: =IF(B6="","",SUMPRODUCT(--(整形回答!F6:BC6=正解キー!$B$2:$B$51)*XLOOKUP(設定!$B$11:$B$60,設定!$A$5:$A$7,設定!$B$5:$B$7)*XLOOKUP(設定!$C$11:$C$60,設定!$D$5:$D$7,設定!$E$5:$E$7))) | E6: =SUMPRODUCT(XLOOKUP(設定!$B$11:$B$60,設定!$A$5:$A$7,設定!$B$5:$B$7)*XLOOKUP(設定!$C$11:$C$60,設定!$D$5:$D$7,設定!$E$5:$E$7)) | F6: =IF(D6="","",D6/E6*100) | G6: =IF(D6="","",IF(SUMPRODUCT(--(設定!$B$11:$B$60="OS（Linux/Windows）")*XLOOKUP(設定!$B$11:$B$60,設定!$A$5:$A$7,設定!$B$5:$B$7)*XLOOKUP(設定!$C$11:$C$60,設定!$D$5:$D$7,設定!$E$5:$E$7))=0,"",SUMPRODUCT(--(設定!$B$11:$B$60="OS（Linux/Windows）")*--(整形回答!F6:BC6=正解キー!$B$2:$B$51)*XLOOKUP(設定!$B$11:$B$60,設定!$A$5:$A$7,設定!$B$5:$B$7)*XLOOKUP(設定!$C$11:$C$60,設定!$D$5:$D$7,設定!$E$5:$E$7))/SUMPRODUCT(--(設定!$B$11:$B$60="OS（Linux/Windows）")*XLOOKUP(設定!$B$11:$B$60,設定!$A$5:$A$7,設定!$B$5:$B$7)*XLOOKUP(設定!$C$11:$C$60,設定!$D$5:$D$7,設定!$E$5:$E$7))*100)) | H6: =IF(D6="","",IF(SUMPRODUCT(--(設定!$B$11:$B$60="AWS")*XLOOKUP(設定!$B$11:$B$60,設定!$A$5:$A$7,設定!$B$5:$B$7)*XLOOKUP(設定!$C$11:$C$60,設定!$D$5:$D$7,設定!$E$5:$E$7))=0,"",SUMPRODUCT(--(設定!$B$11:$B$60="AWS")*--(整形回答!F6:BC6=正解キー!$B$2:$B$51)*XLOOKUP(設定!$B$11:$B$60,設定!$A$5:$A$7,設定!$B$5:$B$7)*XLOOKUP(設定!$C$11:$C$60,設定!$D$5:$D$7,設定!$E$5:$E$7))/SUMPRODUCT(--(設定!$B$11:$B$60="AWS")*XLOOKUP(設定!$B$11:$B$60,設定!$A$5:$A$7,設定!$B$5:$B$7)*XLOOKUP(設定!$C$11:$C$60,設定!$D$5:$D$7,設定!$E$5:$E$7))*100)) | I6: =IF(D6="","",IF(SUMPRODUCT(--(設定!$B$11:$B$60="NW/Security")*XLOOKUP(設定!$B$11:$B$60,設定!$A$5:$A$7,設定!$B$5:$B$7)*XLOOKUP(設定!$C$11:$C$60,設定!$D$5:$D$7,設定!$E$5:$E$7))=0,"",SUMPRODUCT(--(設定!$B$11:$B$60="NW/Security")*--(整形回答!F6:BC6=正解キー!$B$2:$B$51)*XLOOKUP(設定!$B$11:$B$60,設定!$A$5:$A$7,設定!$B$5:$B$7)*XLOOKUP(設定!$C$11:$C$60,設定!$D$5:$D$7,設定!$E$5:$E$7))/SUMPRODUCT(--(設定!$B$11:$B$60="NW/Security")*XLOOKUP(設定!$B$11:$B$60,設定!$A$5:$A$7,設定!$B$5:$B$7)*XLOOKUP(設定!$C$11:$C$60,設定!$D$5:$D$7,設定!$E$5:$E$7))*100)) | J6: =IF(F6="","",IF(F6>=85,"即戦力",IF(F6>=70,"主担当",IF(F6>=55,"サポート","育成")))) | K6: =整形回答!E6
A7: =整形回答!A7 | B7: =整形回答!B7 | C7: =整形回答!C7 | D7: =IF(B7="","",SUMPRODUCT(--(整形回答!F7:BC7=正解キー!$B$2:$B$51)*XLOOKUP(設定!$B$11:$B$60,設定!$A$5:$A$7,設定!$B$5:$B$7)*XLOOKUP(設定!$C$11:$C$60,設定!$D$5:$D$7,設定!$E$5:$E$7))) | E7: =SUMPRODUCT(XLOOKUP(設定!$B$11:$B$60,設定!$A$5:$A$7,設定!$B$5:$B$7)*XLOOKUP(設定!$C$11:$C$60,設定!$D$5:$D$7,設定!$E$5:$E$7)) | F7: =IF(D7="","",D7/E7*100) | G7: =IF(D7="","",IF(SUMPRODUCT(--(設定!$B$11:$B$60="OS（Linux/Windows）")*XLOOKUP(設定!$B$11:$B$60,設定!$A$5:$A$7,設定!$B$5:$B$7)*XLOOKUP(設定!$C$11:$C$60,設定!$D$5:$D$7,設定!$E$5:$E$7))=0,"",SUMPRODUCT(--(設定!$B$11:$B$60="OS（Linux/Windows）")*--(整形回答!F7:BC7=正解キー!$B$2:$B$51)*XLOOKUP(設定!$B$11:$B$60,設定!$A$5:$A$7,設定!$B$5:$B$7)*XLOOKUP(設定!$C$11:$C$60,設定!$D$5:$D$7,設定!$E$5:$E$7))/SUMPRODUCT(--(設定!$B$11:$B$60="OS（Linux/Windows）")*XLOOKUP(設定!$B$11:$B$60,設定!$A$5:$A$7,設定!$B$5:$B$7)*XLOOKUP(設定!$C$11:$C$60,設定!$D$5:$D$7,設定!$E$5:$E$7))*100)) | H7: =IF(D7="","",IF(SUMPRODUCT(--(設定!$B$11:$B$60="AWS")*XLOOKUP(設定!$B$11:$B$60,設定!$A$5:$A$7,設定!$B$5:$B$7)*XLOOKUP(設定!$C$11:$C$60,設定!$D$5:$D$7,設定!$E$5:$E$7))=0,"",SUMPRODUCT(--(設定!$B$11:$B$60="AWS")*--(整形回答!F7:BC7=正解キー!$B$2:$B$51)*XLOOKUP(設定!$B$11:$B$60,設定!$A$5:$A$7,設定!$B$5:$B$7)*XLOOKUP(設定!$C$11:$C$60,設定!$D$5:$D$7,設定!$E$5:$E$7))/SUMPRODUCT(--(設定!$B$11:$B$60="AWS")*XLOOKUP(設定!$B$11:$B$60,設定!$A$5:$A$7,設定!$B$5:$B$7)*XLOOKUP(設定!$C$11:$C$60,設定!$D$5:$D$7,設定!$E$5:$E$7))*100)) | I7: =IF(D7="","",IF(SUMPRODUCT(--(設定!$B$11:$B$60="NW/Security")*XLOOKUP(設定!$B$11:$B$60,設定!$A$5:$A$7,設定!$B$5:$B$7)*XLOOKUP(設定!$C$11:$C$60,設定!$D$5:$D$7,設定!$E$5:$E$7))=0,"",SUMPRODUCT(--(設定!$B$11:$B$60="NW/Security")*--(整形回答!F7:BC7=正解キー!$B$2:$B$51)*XLOOKUP(設定!$B$11:$B$60,設定!$A$5:$A$7,設定!$B$5:$B$7)*XLOOKUP(設定!$C$11:$C$60,設定!$D$5:$D$7,設定!$E$5:$E$7))/SUMPRODUCT(--(設定!$B$11:$B$60="NW/Security")*XLOOKUP(設定!$B$11:$B$60,設定!$A$5:$A$7,設定!$B$5:$B$7)*XLOOKUP(設定!$C$11:$C$60,設定!$D$5:$D$7,設定!$E$5:$E$7))*100)) | J7: =IF(F7="","",IF(F7>=85,"即戦力",IF(F7>=70,"主担当",IF(F7>=55,"サポート","育成")))) | K7: =整形回答!E7
A8: =整形回答!A8 | B8: =整形回答!B8 | C8: =整形回答!C8 | D8: =IF(B8="","",SUMPRODUCT(--(整形回答!F8:BC8=正解キー!$B$2:$B$51)*XLOOKUP(設定!$B$11:$B$60,設定!$A$5:$A$7,設定!$B$5:$B$7)*XLOOKUP(設定!$C$11:$C$60,設定!$D$5:$D$7,設定!$E$5:$E$7))) | E8: =SUMPRODUCT(XLOOKUP(設定!$B$11:$B$60,設定!$A$5:$A$7,設定!$B$5:$B$7)*XLOOKUP(設定!$C$11:$C$60,設定!$D$5:$D$7,設定!$E$5:$E$7)) | F8: =IF(D8="","",D8/E8*100) | G8: =IF(D8="","",IF(SUMPRODUCT(--(設定!$B$11:$B$60="OS（Linux/Windows）")*XLOOKUP(設定!$B$11:$B$60,設定!$A$5:$A$7,設定!$B$5:$B$7)*XLOOKUP(設定!$C$11:$C$60,設定!$D$5:$D$7,設定!$E$5:$E$7))=0,"",SUMPRODUCT(--(設定!$B$11:$B$60="OS（Linux/Windows）")*--(整形回答!F8:BC8=正解キー!$B$2:$B$51)*XLOOKUP(設定!$B$11:$B$60,設定!$A$5:$A$7,設定!$B$5:$B$7)*XLOOKUP(設定!$C$11:$C$60,設定!$D$5:$D$7,設定!$E$5:$E$7))/SUMPRODUCT(--(設定!$B$11:$B$60="OS（Linux/Windows）")*XLOOKUP(設定!$B$11:$B$60,設定!$A$5:$A$7,設定!$B$5:$B$7)*XLOOKUP(設定!$C$11:$C$60,設定!$D$5:$D$7,設定!$E$5:$E$7))*100)) | H8: =IF(D8="","",IF(SUMPRODUCT(--(設定!$B$11:$B$60="AWS")*XLOOKUP(設定!$B$11:$B$60,設定!$A$5:$A$7,設定!$B$5:$B$7)*XLOOKUP(設定!$C$11:$C$60,設定!$D$5:$D$7,設定!$E$5:$E$7))=0,"",SUMPRODUCT(--(設定!$B$11:$B$60="AWS")*--(整形回答!F8:BC8=正解キー!$B$2:$B$51)*XLOOKUP(設定!$B$11:$B$60,設定!$A$5:$A$7,設定!$B$5:$B$7)*XLOOKUP(設定!$C$11:$C$60,設定!$D$5:$D$7,設定!$E$5:$E$7))/SUMPRODUCT(--(設定!$B$11:$B$60="AWS")*XLOOKUP(設定!$B$11:$B$60,設定!$A$5:$A$7,設定!$B$5:$B$7)*XLOOKUP(設定!$C$11:$C$60,設定!$D$5:$D$7,設定!$E$5:$E$7))*100)) | I8: =IF(D8="","",IF(SUMPRODUCT(--(設定!$B$11:$B$60="NW/Security")*XLOOKUP(設定!$B$11:$B$60,設定!$A$5:$A$7,設定!$B$5:$B$7)*XLOOKUP(設定!$C$11:$C$60,設定!$D$5:$D$7,設定!$E$5:$E$7))=0,"",SUMPRODUCT(--(設定!$B$11:$B$60="NW/Security")*--(整形回答!F8:BC8=正解キー!$B$2:$B$51)*XLOOKUP(設定!$B$11:$B$60,設定!$A$5:$A$7,設定!$B$5:$B$7)*XLOOKUP(設定!$C$11:$C$60,設定!$D$5:$D$7,設定!$E$5:$E$7))/SUMPRODUCT(--(設定!$B$11:$B$60="NW/Security")*XLOOKUP(設定!$B$11:$B$60,設定!$A$5:$A$7,設定!$B$5:$B$7)*XLOOKUP(設定!$C$11:$C$60,設定!$D$5:$D$7,設定!$E$5:$E$7))*100)) | J8: =IF(F8="","",IF(F8>=85,"即戦力",IF(F8>=70,"主担当",IF(F8>=55,"サポート","育成")))) | K8: =整形回答!E8
A9: =整形回答!A9 | B9: =整形回答!B9 | C9: =整形回答!C9 | D9: =IF(B9="","",SUMPRODUCT(--(整形回答!F9:BC9=正解キー!$B$2:$B$51)*XLOOKUP(設定!$B$11:$B$60,設定!$A$5:$A$7,設定!$B$5:$B$7)*XLOOKUP(設定!$C$11:$C$60,設定!$D$5:$D$7,設定!$E$5:$E$7))) | E9: =SUMPRODUCT(XLOOKUP(設定!$B$11:$B$60,設定!$A$5:$A$7,設定!$B$5:$B$7)*XLOOKUP(設定!$C$11:$C$60,設定!$D$5:$D$7,設定!$E$5:$E$7)) | F9: =IF(D9="","",D9/E9*100) | G9: =IF(D9="","",IF(SUMPRODUCT(--(設定!$B$11:$B$60="OS（Linux/Windows）")*XLOOKUP(設定!$B$11:$B$60,設定!$A$5:$A$7,設定!$B$5:$B$7)*XLOOKUP(設定!$C$11:$C$60,設定!$D$5:$D$7,設定!$E$5:$E$7))=0,"",SUMPRODUCT(--(設定!$B$11:$B$60="OS（Linux/Windows）")*--(整形回答!F9:BC9=正解キー!$B$2:$B$51)*XLOOKUP(設定!$B$11:$B$60,設定!$A$5:$A$7,設定!$B$5:$B$7)*XLOOKUP(設定!$C$11:$C$60,設定!$D$5:$D$7,設定!$E$5:$E$7))/SUMPRODUCT(--(設定!$B$11:$B$60="OS（Linux/Windows）")*XLOOKUP(設定!$B$11:$B$60,設定!$A$5:$A$7,設定!$B$5:$B$7)*XLOOKUP(設定!$C$11:$C$60,設定!$D$5:$D$7,設定!$E$5:$E$7))*100)) | H9: =IF(D9="","",IF(SUMPRODUCT(--(設定!$B$11:$B$60="AWS")*XLOOKUP(設定!$B$11:$B$60,設定!$A$5:$A$7,設定!$B$5:$B$7)*XLOOKUP(設定!$C$11:$C$60,設定!$D$5:$D$7,設定!$E$5:$E$7))=0,"",SUMPRODUCT(--(設定!$B$11:$B$60="AWS")*--(整形回答!F9:BC9=正解キー!$B$2:$B$51)*XLOOKUP(設定!$B$11:$B$60,設定!$A$5:$A$7,設定!$B$5:$B$7)*XLOOKUP(設定!$C$11:$C$60,設定!$D$5:$D$7,設定!$E$5:$E$7))/SUMPRODUCT(--(設定!$B$11:$B$60="AWS")*XLOOKUP(設定!$B$11:$B$60,設定!$A$5:$A$7,設定!$B$5:$B$7)*XLOOKUP(設定!$C$11:$C$60,設定!$D$5:$D$7,設定!$E$5:$E$7))*100)) | I9: =IF(D9="","",IF(SUMPRODUCT(--(設定!$B$11:$B$60="NW/Security")*XLOOKUP(設定!$B$11:$B$60,設定!$A$5:$A$7,設定!$B$5:$B$7)*XLOOKUP(設定!$C$11:$C$60,設定!$D$5:$D$7,設定!$E$5:$E$7))=0,"",SUMPRODUCT(--(設定!$B$11:$B$60="NW/Security")*--(整形回答!F9:BC9=正解キー!$B$2:$B$51)*XLOOKUP(設定!$B$11:$B$60,設定!$A$5:$A$7,設定!$B$5:$B$7)*XLOOKUP(設定!$C$11:$C$60,設定!$D$5:$D$7,設定!$E$5:$E$7))/SUMPRODUCT(--(設定!$B$11:$B$60="NW/Security")*XLOOKUP(設定!$B$11:$B$60,設定!$A$5:$A$7,設定!$B$5:$B$7)*XLOOKUP(設定!$C$11:$C$60,設定!$D$5:$D$7,設定!$E$5:$E$7))*100)) | J9: =IF(F9="","",IF(F9>=85,"即戦力",IF(F9>=70,"主担当",IF(F9>=55,"サポート","育成")))) | K9: =整形回答!E9
A10: =整形回答!A10 | B10: =整形回答!B10 | C10: =整形回答!C10 | D10: =IF(B10="","",SUMPRODUCT(--(整形回答!F10:BC10=正解キー!$B$2:$B$51)*XLOOKUP(設定!$B$11:$B$60,設定!$A$5:$A$7,設定!$B$5:$B$7)*XLOOKUP(設定!$C$11:$C$60,設定!$D$5:$D$7,設定!$E$5:$E$7))) | E10: =SUMPRODUCT(XLOOKUP(設定!$B$11:$B$60,設定!$A$5:$A$7,設定!$B$5:$B$7)*XLOOKUP(設定!$C$11:$C$60,設定!$D$5:$D$7,設定!$E$5:$E$7)) | F10: =IF(D10="","",D10/E10*100) | G10: =IF(D10="","",IF(SUMPRODUCT(--(設定!$B$11:$B$60="OS（Linux/Windows）")*XLOOKUP(設定!$B$11:$B$60,設定!$A$5:$A$7,設定!$B$5:$B$7)*XLOOKUP(設定!$C$11:$C$60,設定!$D$5:$D$7,設定!$E$5:$E$7))=0,"",SUMPRODUCT(--(設定!$B$11:$B$60="OS（Linux/Windows）")*--(整形回答!F10:BC10=正解キー!$B$2:$B$51)*XLOOKUP(設定!$B$11:$B$60,設定!$A$5:$A$7,設定!$B$5:$B$7)*XLOOKUP(設定!$C$11:$C$60,設定!$D$5:$D$7,設定!$E$5:$E$7))/SUMPRODUCT(--(設定!$B$11:$B$60="OS（Linux/Windows）")*XLOOKUP(設定!$B$11:$B$60,設定!$A$5:$A$7,設定!$B$5:$B$7)*XLOOKUP(設定!$C$11:$C$60,設定!$D$5:$D$7,設定!$E$5:$E$7))*100)) | H10: =IF(D10="","",IF(SUMPRODUCT(--(設定!$B$11:$B$60="AWS")*XLOOKUP(設定!$B$11:$B$60,設定!$A$5:$A$7,設定!$B$5:$B$7)*XLOOKUP(設定!$C$11:$C$60,設定!$D$5:$D$7,設定!$E$5:$E$7))=0,"",SUMPRODUCT(--(設定!$B$11:$B$60="AWS")*--(整形回答!F10:BC10=正解キー!$B$2:$B$51)*XLOOKUP(設定!$B$11:$B$60,設定!$A$5:$A$7,設定!$B$5:$B$7)*XLOOKUP(設定!$C$11:$C$60,設定!$D$5:$D$7,設定!$E$5:$E$7))/SUMPRODUCT(--(設定!$B$11:$B$60="AWS")*XLOOKUP(設定!$B$11:$B$60,設定!$A$5:$A$7,設定!$B$5:$B$7)*XLOOKUP(設定!$C$11:$C$60,設定!$D$5:$D$7,設定!$E$5:$E$7))*100)) | I10: =IF(D10="","",IF(SUMPRODUCT(--(設定!$B$11:$B$60="NW/Security")*XLOOKUP(設定!$B$11:$B$60,設定!$A$5:$A$7,設定!$B$5:$B$7)*XLOOKUP(設定!$C$11:$C$60,設定!$D$5:$D$7,設定!$E$5:$E$7))=0,"",SUMPRODUCT(--(設定!$B$11:$B$60="NW/Security")*--(整形回答!F10:BC10=正解キー!$B$2:$B$51)*XLOOKUP(設定!$B$11:$B$60,設定!$A$5:$A$7,設定!$B$5:$B$7)*XLOOKUP(設定!$C$11:$C$60,設定!$D$5:$D$7,設定!$E$5:$E$7))/SUMPRODUCT(--(設定!$B$11:$B$60="NW/Security")*XLOOKUP(設定!$B$11:$B$60,設定!$A$5:$A$7,設定!$B$5:$B$7)*XLOOKUP(設定!$C$11:$C$60,設定!$D$5:$D$7,設定!$E$5:$E$7))*100)) | J10: =IF(F10="","",IF(F10>=85,"即戦力",IF(F10>=70,"主担当",IF(F10>=55,"サポート","育成")))) | K10: =整形回答!E10
A11: =整形回答!A11 | B11: =整形回答!B11 | C11: =整形回答!C11 | D11: =IF(B11="","",SUMPRODUCT(--(整形回答!F11:BC11=正解キー!$B$2:$B$51)*XLOOKUP(設定!$B$11:$B$60,設定!$A$5:$A$7,設定!$B$5:$B$7)*XLOOKUP(設定!$C$11:$C$60,設定!$D$5:$D$7,設定!$E$5:$E$7))) | E11: =SUMPRODUCT(XLOOKUP(設定!$B$11:$B$60,設定!$A$5:$A$7,設定!$B$5:$B$7)*XLOOKUP(設定!$C$11:$C$60,設定!$D$5:$D$7,設定!$E$5:$E$7)) | F11: =IF(D11="","",D11/E11*100) | G11: =IF(D11="","",IF(SUMPRODUCT(--(設定!$B$11:$B$60="OS（Linux/Windows）")*XLOOKUP(設定!$B$11:$B$60,設定!$A$5:$A$7,設定!$B$5:$B$7)*XLOOKUP(設定!$C$11:$C$60,設定!$D$5:$D$7,設定!$E$5:$E$7))=0,"",SUMPRODUCT(--(設定!$B$11:$B$60="OS（Linux/Windows）")*--(整形回答!F11:BC11=正解キー!$B$2:$B$51)*XLOOKUP(設定!$B$11:$B$60,設定!$A$5:$A$7,設定!$B$5:$B$7)*XLOOKUP(設定!$C$11:$C$60,設定!$D$5:$D$7,設定!$E$5:$E$7))/SUMPRODUCT(--(設定!$B$11:$B$60="OS（Linux/Windows）")*XLOOKUP(設定!$B$11:$B$60,設定!$A$5:$A$7,設定!$B$5:$B$7)*XLOOKUP(設定!$C$11:$C$60,設定!$D$5:$D$7,設定!$E$5:$E$7))*100)) | H11: =IF(D11="","",IF(SUMPRODUCT(--(設定!$B$11:$B$60="AWS")*XLOOKUP(設定!$B$11:$B$60,設定!$A$5:$A$7,設定!$B$5:$B$7)*XLOOKUP(設定!$C$11:$C$60,設定!$D$5:$D$7,設定!$E$5:$E$7))=0,"",SUMPRODUCT(--(設定!$B$11:$B$60="AWS")*--(整形回答!F11:BC11=正解キー!$B$2:$B$51)*XLOOKUP(設定!$B$11:$B$60,設定!$A$5:$A$7,設定!$B$5:$B$7)*XLOOKUP(設定!$C$11:$C$60,設定!$D$5:$D$7,設定!$E$5:$E$7))/SUMPRODUCT(--(設定!$B$11:$B$60="AWS")*XLOOKUP(設定!$B$11:$B$60,設定!$A$5:$A$7,設定!$B$5:$B$7)*XLOOKUP(設定!$C$11:$C$60,設定!$D$5:$D$7,設定!$E$5:$E$7))*100)) | I11: =IF(D11="","",IF(SUMPRODUCT(--(設定!$B$11:$B$60="NW/Security")*XLOOKUP(設定!$B$11:$B$60,設定!$A$5:$A$7,設定!$B$5:$B$7)*XLOOKUP(設定!$C$11:$C$60,設定!$D$5:$D$7,設定!$E$5:$E$7))=0,"",SUMPRODUCT(--(設定!$B$11:$B$60="NW/Security")*--(整形回答!F11:BC11=正解キー!$B$2:$B$51)*XLOOKUP(設定!$B$11:$B$60,設定!$A$5:$A$7,設定!$B$5:$B$7)*XLOOKUP(設定!$C$11:$C$60,設定!$D$5:$D$7,設定!$E$5:$E$7))/SUMPRODUCT(--(設定!$B$11:$B$60="NW/Security")*XLOOKUP(設定!$B$11:$B$60,設定!$A$5:$A$7,設定!$B$5:$B$7)*XLOOKUP(設定!$C$11:$C$60,設定!$D$5:$D$7,設定!$E$5:$E$7))*100)) | J11: =IF(F11="","",IF(F11>=85,"即戦力",IF(F11>=70,"主担当",IF(F11>=55,"サポート","育成")))) | K11: =整形回答!E11
A12: =整形回答!A12 | B12: =整形回答!B12 | C12: =整形回答!C12 | D12: =IF(B12="","",SUMPRODUCT(--(整形回答!F12:BC12=正解キー!$B$2:$B$51)*XLOOKUP(設定!$B$11:$B$60,設定!$A$5:$A$7,設定!$B$5:$B$7)*XLOOKUP(設定!$C$11:$C$60,設定!$D$5:$D$7,設定!$E$5:$E$7))) | E12: =SUMPRODUCT(XLOOKUP(設定!$B$11:$B$60,設定!$A$5:$A$7,設定!$B$5:$B$7)*XLOOKUP(設定!$C$11:$C$60,設定!$D$5:$D$7,設定!$E$5:$E$7)) | F12: =IF(D12="","",D12/E12*100) | G12: =IF(D12="","",IF(SUMPRODUCT(--(設定!$B$11:$B$60="OS（Linux/Windows）")*XLOOKUP(設定!$B$11:$B$60,設定!$A$5:$A$7,設定!$B$5:$B$7)*XLOOKUP(設定!$C$11:$C$60,設定!$D$5:$D$7,設定!$E$5:$E$7))=0,"",SUMPRODUCT(--(設定!$B$11:$B$60="OS（Linux/Windows）")*--(整形回答!F12:BC12=正解キー!$B$2:$B$51)*XLOOKUP(設定!$B$11:$B$60,設定!$A$5:$A$7,設定!$B$5:$B$7)*XLOOKUP(設定!$C$11:$C$60,設定!$D$5:$D$7,設定!$E$5:$E$7))/SUMPRODUCT(--(設定!$B$11:$B$60="OS（Linux/Windows）")*XLOOKUP(設定!$B$11:$B$60,設定!$A$5:$A$7,設定!$B$5:$B$7)*XLOOKUP(設定!$C$11:$C$60,設定!$D$5:$D$7,設定!$E$5:$E$7))*100)) | H12: =IF(D12="","",IF(SUMPRODUCT(--(設定!$B$11:$B$60="AWS")*XLOOKUP(設定!$B$11:$B$60,設定!$A$5:$A$7,設定!$B$5:$B$7)*XLOOKUP(設定!$C$11:$C$60,設定!$D$5:$D$7,設定!$E$5:$E$7))=0,"",SUMPRODUCT(--(設定!$B$11:$B$60="AWS")*--(整形回答!F12:BC12=正解キー!$B$2:$B$51)*XLOOKUP(設定!$B$11:$B$60,設定!$A$5:$A$7,設定!$B$5:$B$7)*XLOOKUP(設定!$C$11:$C$60,設定!$D$5:$D$7,設定!$E$5:$E$7))/SUMPRODUCT(--(設定!$B$11:$B$60="AWS")*XLOOKUP(設定!$B$11:$B$60,設定!$A$5:$A$7,設定!$B$5:$B$7)*XLOOKUP(設定!$C$11:$C$60,設定!$D$5:$D$7,設定!$E$5:$E$7))*100)) | I12: =IF(D12="","",IF(SUMPRODUCT(--(設定!$B$11:$B$60="NW/Security")*XLOOKUP(設定!$B$11:$B$60,設定!$A$5:$A$7,設定!$B$5:$B$7)*XLOOKUP(設定!$C$11:$C$60,設定!$D$5:$D$7,設定!$E$5:$E$7))=0,"",SUMPRODUCT(--(設定!$B$11:$B$60="NW/Security")*--(整形回答!F12:BC12=正解キー!$B$2:$B$51)*XLOOKUP(設定!$B$11:$B$60,設定!$A$5:$A$7,設定!$B$5:$B$7)*XLOOKUP(設定!$C$11:$C$60,設定!$D$5:$D$7,設定!$E$5:$E$7))/SUMPRODUCT(--(設定!$B$11:$B$60="NW/Security")*XLOOKUP(設定!$B$11:$B$60,設定!$A$5:$A$7,設定!$B$5:$B$7)*XLOOKUP(設定!$C$11:$C$60,設定!$D$5:$D$7,設定!$E$5:$E$7))*100)) | J12: =IF(F12="","",IF(F12>=85,"即戦力",IF(F12>=70,"主担当",IF(F12>=55,"サポート","育成")))) | K12: =整形回答!E12
A13: =整形回答!A13 | B13: =整形回答!B13 | C13: =整形回答!C13 | D13: =IF(B13="","",SUMPRODUCT(--(整形回答!F13:BC13=正解キー!$B$2:$B$51)*XLOOKUP(設定!$B$11:$B$60,設定!$A$5:$A$7,設定!$B$5:$B$7)*XLOOKUP(設定!$C$11:$C$60,設定!$D$5:$D$7,設定!$E$5:$E$7))) | E13: =SUMPRODUCT(XLOOKUP(設定!$B$11:$B$60,設定!$A$5:$A$7,設定!$B$5:$B$7)*XLOOKUP(設定!$C$11:$C$60,設定!$D$5:$D$7,設定!$E$5:$E$7)) | F13: =IF(D13="","",D13/E13*100) | G13: =IF(D13="","",IF(SUMPRODUCT(--(設定!$B$11:$B$60="OS（Linux/Windows）")*XLOOKUP(設定!$B$11:$B$60,設定!$A$5:$A$7,設定!$B$5:$B$7)*XLOOKUP(設定!$C$11:$C$60,設定!$D$5:$D$7,設定!$E$5:$E$7))=0,"",SUMPRODUCT(--(設定!$B$11:$B$60="OS（Linux/Windows）")*--(整形回答!F13:BC13=正解キー!$B$2:$B$51)*XLOOKUP(設定!$B$11:$B$60,設定!$A$5:$A$7,設定!$B$5:$B$7)*XLOOKUP(設定!$C$11:$C$60,設定!$D$5:$D$7,設定!$E$5:$E$7))/SUMPRODUCT(--(設定!$B$11:$B$60="OS（Linux/Windows）")*XLOOKUP(設定!$B$11:$B$60,設定!$A$5:$A$7,設定!$B$5:$B$7)*XLOOKUP(設定!$C$11:$C$60,設定!$D$5:$D$7,設定!$E$5:$E$7))*100)) | H13: =IF(D13="","",IF(SUMPRODUCT(--(設定!$B$11:$B$60="AWS")*XLOOKUP(設定!$B$11:$B$60,設定!$A$5:$A$7,設定!$B$5:$B$7)*XLOOKUP(設定!$C$11:$C$60,設定!$D$5:$D$7,設定!$E$5:$E$7))=0,"",SUMPRODUCT(--(設定!$B$11:$B$60="AWS")*--(整形回答!F13:BC13=正解キー!$B$2:$B$51)*XLOOKUP(設定!$B$11:$B$60,設定!$A$5:$A$7,設定!$B$5:$B$7)*XLOOKUP(設定!$C$11:$C$60,設定!$D$5:$D$7,設定!$E$5:$E$7))/SUMPRODUCT(--(設定!$B$11:$B$60="AWS")*XLOOKUP(設定!$B$11:$B$60,設定!$A$5:$A$7,設定!$B$5:$B$7)*XLOOKUP(設定!$C$11:$C$60,設定!$D$5:$D$7,設定!$E$5:$E$7))*100)) | I13: =IF(D13="","",IF(SUMPRODUCT(--(設定!$B$11:$B$60="NW/Security")*XLOOKUP(設定!$B$11:$B$60,設定!$A$5:$A$7,設定!$B$5:$B$7)*XLOOKUP(設定!$C$11:$C$60,設定!$D$5:$D$7,設定!$E$5:$E$7))=0,"",SUMPRODUCT(--(設定!$B$11:$B$60="NW/Security")*--(整形回答!F13:BC13=正解キー!$B$2:$B$51)*XLOOKUP(設定!$B$11:$B$60,設定!$A$5:$A$7,設定!$B$5:$B$7)*XLOOKUP(設定!$C$11:$C$60,設定!$D$5:$D$7,設定!$E$5:$E$7))/SUMPRODUCT(--(設定!$B$11:$B$60="NW/Security")*XLOOKUP(設定!$B$11:$B$60,設定!$A$5:$A$7,設定!$B$5:$B$7)*XLOOKUP(設定!$C$11:$C$60,設定!$D$5:$D$7,設定!$E$5:$E$7))*100)) | J13: =IF(F13="","",IF(F13>=85,"即戦力",IF(F13>=70,"主担当",IF(F13>=55,"サポート","育成")))) | K13: =整形回答!E13
A14: =整形回答!A14 | B14: =整形回答!B14 | C14: =整形回答!C14 | D14: =IF(B14="","",SUMPRODUCT(--(整形回答!F14:BC14=正解キー!$B$2:$B$51)*XLOOKUP(設定!$B$11:$B$60,設定!$A$5:$A$7,設定!$B$5:$B$7)*XLOOKUP(設定!$C$11:$C$60,設定!$D$5:$D$7,設定!$E$5:$E$7))) | E14: =SUMPRODUCT(XLOOKUP(設定!$B$11:$B$60,設定!$A$5:$A$7,設定!$B$5:$B$7)*XLOOKUP(設定!$C$11:$C$60,設定!$D$5:$D$7,設定!$E$5:$E$7)) | F14: =IF(D14="","",D14/E14*100) | G14: =IF(D14="","",IF(SUMPRODUCT(--(設定!$B$11:$B$60="OS（Linux/Windows）")*XLOOKUP(設定!$B$11:$B$60,設定!$A$5:$A$7,設定!$B$5:$B$7)*XLOOKUP(設定!$C$11:$C$60,設定!$D$5:$D$7,設定!$E$5:$E$7))=0,"",SUMPRODUCT(--(設定!$B$11:$B$60="OS（Linux/Windows）")*--(整形回答!F14:BC14=正解キー!$B$2:$B$51)*XLOOKUP(設定!$B$11:$B$60,設定!$A$5:$A$7,設定!$B$5:$B$7)*XLOOKUP(設定!$C$11:$C$60,設定!$D$5:$D$7,設定!$E$5:$E$7))/SUMPRODUCT(--(設定!$B$11:$B$60="OS（Linux/Windows）")*XLOOKUP(設定!$B$11:$B$60,設定!$A$5:$A$7,設定!$B$5:$B$7)*XLOOKUP(設定!$C$11:$C$60,設定!$D$5:$D$7,設定!$E$5:$E$7))*100)) | H14: =IF(D14="","",IF(SUMPRODUCT(--(設定!$B$11:$B$60="AWS")*XLOOKUP(設定!$B$11:$B$60,設定!$A$5:$A$7,設定!$B$5:$B$7)*XLOOKUP(設定!$C$11:$C$60,設定!$D$5:$D$7,設定!$E$5:$E$7))=0,"",SUMPRODUCT(--(設定!$B$11:$B$60="AWS")*--(整形回答!F14:BC14=正解キー!$B$2:$B$51)*XLOOKUP(設定!$B$11:$B$60,設定!$A$5:$A$7,設定!$B$5:$B$7)*XLOOKUP(設定!$C$11:$C$60,設定!$D$5:$D$7,設定!$E$5:$E$7))/SUMPRODUCT(--(設定!$B$11:$B$60="AWS")*XLOOKUP(設定!$B$11:$B$60,設定!$A$5:$A$7,設定!$B$5:$B$7)*XLOOKUP(設定!$C$11:$C$60,設定!$D$5:$D$7,設定!$E$5:$E$7))*100)) | I14: =IF(D14="","",IF(SUMPRODUCT(--(設定!$B$11:$B$60="NW/Security")*XLOOKUP(設定!$B$11:$B$60,設定!$A$5:$A$7,設定!$B$5:$B$7)*XLOOKUP(設定!$C$11:$C$60,設定!$D$5:$D$7,設定!$E$5:$E$7))=0,"",SUMPRODUCT(--(設定!$B$11:$B$60="NW/Security")*--(整形回答!F14:BC14=正解キー!$B$2:$B$51)*XLOOKUP(設定!$B$11:$B$60,設定!$A$5:$A$7,設定!$B$5:$B$7)*XLOOKUP(設定!$C$11:$C$60,設定!$D$5:$D$7,設定!$E$5:$E$7))/SUMPRODUCT(--(設定!$B$11:$B$60="NW/Security")*XLOOKUP(設定!$B$11:$B$60,設定!$A$5:$A$7,設定!$B$5:$B$7)*XLOOKUP(設定!$C$11:$C$60,設定!$D$5:$D$7,設定!$E$5:$E$7))*100)) | J14: =IF(F14="","",IF(F14>=85,"即戦力",IF(F14>=70,"主担当",IF(F14>=55,"サポート","育成")))) | K14: =整形回答!E14
A15: =整形回答!A15 | B15: =整形回答!B15 | C15: =整形回答!C15 | D15: =IF(B15="","",SUMPRODUCT(--(整形回答!F15:BC15=正解キー!$B$2:$B$51)*XLOOKUP(設定!$B$11:$B$60,設定!$A$5:$A$7,設定!$B$5:$B$7)*XLOOKUP(設定!$C$11:$C$60,設定!$D$5:$D$7,設定!$E$5:$E$7))) | E15: =SUMPRODUCT(XLOOKUP(設定!$B$11:$B$60,設定!$A$5:$A$7,設定!$B$5:$B$7)*XLOOKUP(設定!$C$11:$C$60,設定!$D$5:$D$7,設定!$E$5:$E$7)) | F15: =IF(D15="","",D15/E15*100) | G15: =IF(D15="","",IF(SUMPRODUCT(--(設定!$B$11:$B$60="OS（Linux/Windows）")*XLOOKUP(設定!$B$11:$B$60,設定!$A$5:$A$7,設定!$B$5:$B$7)*XLOOKUP(設定!$C$11:$C$60,設定!$D$5:$D$7,設定!$E$5:$E$7))=0,"",SUMPRODUCT(--(設定!$B$11:$B$60="OS（Linux/Windows）")*--(整形回答!F15:BC15=正解キー!$B$2:$B$51)*XLOOKUP(設定!$B$11:$B$60,設定!$A$5:$A$7,設定!$B$5:$B$7)*XLOOKUP(設定!$C$11:$C$60,設定!$D$5:$D$7,設定!$E$5:$E$7))/SUMPRODUCT(--(設定!$B$11:$B$60="OS（Linux/Windows）")*XLOOKUP(設定!$B$11:$B$60,設定!$A$5:$A$7,設定!$B$5:$B$7)*XLOOKUP(設定!$C$11:$C$60,設定!$D$5:$D$7,設定!$E$5:$E$7))*100)) | H15: =IF(D15="","",IF(SUMPRODUCT(--(設定!$B$11:$B$60="AWS")*XLOOKUP(設定!$B$11:$B$60,設定!$A$5:$A$7,設定!$B$5:$B$7)*XLOOKUP(設定!$C$11:$C$60,設定!$D$5:$D$7,設定!$E$5:$E$7))=0,"",SUMPRODUCT(--(設定!$B$11:$B$60="AWS")*--(整形回答!F15:BC15=正解キー!$B$2:$B$51)*XLOOKUP(設定!$B$11:$B$60,設定!$A$5:$A$7,設定!$B$5:$B$7)*XLOOKUP(設定!$C$11:$C$60,設定!$D$5:$D$7,設定!$E$5:$E$7))/SUMPRODUCT(--(設定!$B$11:$B$60="AWS")*XLOOKUP(設定!$B$11:$B$60,設定!$A$5:$A$7,設定!$B$5:$B$7)*XLOOKUP(設定!$C$11:$C$60,設定!$D$5:$D$7,設定!$E$5:$E$7))*100)) | I15: =IF(D15="","",IF(SUMPRODUCT(--(設定!$B$11:$B$60="NW/Security")*XLOOKUP(設定!$B$11:$B$60,設定!$A$5:$A$7,設定!$B$5:$B$7)*XLOOKUP(設定!$C$11:$C$60,設定!$D$5:$D$7,設定!$E$5:$E$7))=0,"",SUMPRODUCT(--(設定!$B$11:$B$60="NW/Security")*--(整形回答!F15:BC15=正解キー!$B$2:$B$51)*XLOOKUP(設定!$B$11:$B$60,設定!$A$5:$A$7,設定!$B$5:$B$7)*XLOOKUP(設定!$C$11:$C$60,設定!$D$5:$D$7,設定!$E$5:$E$7))/SUMPRODUCT(--(設定!$B$11:$B$60="NW/Security")*XLOOKUP(設定!$B$11:$B$60,設定!$A$5:$A$7,設定!$B$5:$B$7)*XLOOKUP(設定!$C$11:$C$60,設定!$D$5:$D$7,設定!$E$5:$E$7))*100)) | J15: =IF(F15="","",IF(F15>=85,"即戦力",IF(F15>=70,"主担当",IF(F15>=55,"サポート","育成")))) | K15: =整形回答!E15
